<?xml version="1.0" encoding="utf-8"?>
<!-- =================================================================================== -->
<!-- |    This document was autogenerated by xacro from lara3.urdf.xacro               | -->
<!-- |    EDITING THIS FILE BY HAND IS NOT RECOMMENDED                                 | -->
<!-- =================================================================================== -->
<robot name="lara3" xmlns:controller="http://playerstage.sourceforge.net/gazebo/xmlschema/#controller" xmlns:interface="http://playerstage.sourceforge.net/gazebo/xmlschema/#interface" xmlns:sensor="http://playerstage.sourceforge.net/gazebo/xmlschema/#sensor">
  <!-- values not comfirmed. 12/05/2022 heitmann-->
  <material name="white">
    <color rgba="1 1 1 1"/>
  </material>
  <!-- ============================ BASE ================================= -->
  <link name="lara3_root_link">
  </link>
  <joint name="lara3_root_joint" type="fixed">
    <origin rpy="0 -1.57079632679 0" xyz="0 0 0"/>
    <axis xyz="0 0 1"/>
    <parent link="lara3_root_link"/>
    <child link="lara3_link0"/>
  </joint>
  <link name="lara3_link0">
    <inertial>
      <mass value="2.133"/>
      <origin rpy="0 0 0" xyz="0.0 0.0 0.0"/>
      <inertia ixx="0.0" ixy="0.0" ixz="0.0" iyy="0.0" iyz="0.0" izz="0.0"/>
    </inertial>
    <visual>
      <origin rpy="0 0 0" xyz="0 0 0"/>
      <geometry>
        <mesh filename="package://example-robot-data/robots/neura_robotics/neura_robot_description-devel-lara3/lara3/meshes/Link0_body.stl"/>
      </geometry>
      <material name="white"/>
    </visual>
    <visual>
      <origin rpy="0 0 0" xyz="0 0 0"/>
      <geometry>
        <mesh filename="package://example-robot-data/robots/neura_robotics/neura_robot_description-devel-lara3/lara3/meshes/Link0_connector.stl"/>
      </geometry>
      <material name="white"/>
    </visual>
    <collision>
      <origin rpy="0 0 0" xyz="0 0 0"/>
      <geometry>
        <mesh filename="package://example-robot-data/robots/neura_robotics/neura_robot_description-devel-lara3/lara3/collision/Link0_body.stl"/>
      </geometry>
      <material name="white"/>
    </collision>
  </link>
  <!-- ============================ DOF1 ================================= -->
  <joint name="lara3_joint1" type="revolute">
    <origin rpy="0 0 1.57079632679" xyz="0.1925 0 0"/>
    <axis xyz="0 -1 0"/>
    <limit effort="204" lower="-3.14159" upper="3.14159" velocity="3.14159"/>
    <parent link="lara3_link0"/>
    <child link="lara3_link1"/>
  </joint>
  <link name="lara3_link1">
    <inertial>
      <mass value="4.697"/>
      <origin rpy="0 0 0" xyz="0.02107 0.047171 -1.8e-05"/>
      <inertia ixx="0.016186" ixy="0.0" ixz="0.003788" iyy="0.019981" iyz="-2e-06" izz="0.009748"/>
    </inertial>
    <visual>
      <origin rpy="0 0 0" xyz="0 0 0"/>
      <geometry>
        <mesh filename="package://example-robot-data/robots/neura_robotics/neura_robot_description-devel-lara3/lara3/meshes/Link1_body.stl"/>
      </geometry>
      <material name="white"/>
    </visual>
    <visual>
      <origin rpy="0 0 0" xyz="0 0 0"/>
      <geometry>
        <mesh filename="package://example-robot-data/robots/neura_robotics/neura_robot_description-devel-lara3/lara3/meshes/Link1_rings.stl"/>
      </geometry>
      <material name="white"/>
    </visual>
    <collision>
      <origin rpy="0 0 0" xyz="0 0 0"/>
      <geometry>
        <mesh filename="package://example-robot-data/robots/neura_robotics/neura_robot_description-devel-lara3/lara3/collision/Link1_body.stl"/>
      </geometry>
      <material name="white"/>
    </collision>
  </link>
  <!-- ============================ DOF2 ================================= -->
  <joint name="lara3_joint2" type="revolute">
    <origin rpy="0 0 -4.89652762781e-12" xyz="0 0 0"/>
    <axis xyz="1 0 0"/>
    <limit effort="204" lower="-2.3492" upper="2.3492" velocity="2.3492"/>
    <!--<safety_controller k_position="100" k_velocity="2" soft_lower_limit="-2.105948851735" soft_upper_limit="2.105948851735" />-->
    <!-- <dynamics damping="13.0" friction="9.0" /> -->
    <parent link="lara3_link1"/>
    <child link="lara3_link2"/>
  </joint>
  <link name="lara3_link2">
    <inertial>
      <mass value="1.606"/>
      <origin rpy="0 0 0" xyz="0.108666 -0.12227 -2e-05"/>
      <inertia ixx="0.01686" ixy="-4e-06" ixz="0.0" iyy="0.001656" iyz="0.000818" izz="0.017453"/>
    </inertial>
    <visual>
      <origin rpy="0 0 0" xyz="0 0 0"/>
      <geometry>
        <mesh filename="package://example-robot-data/robots/neura_robotics/neura_robot_description-devel-lara3/lara3/meshes/Link2_body.stl"/>
      </geometry>
      <material name="white"/>
    </visual>
    <collision>
      <origin rpy="0 0 0" xyz="0 0 0"/>
      <geometry>
        <mesh filename="package://example-robot-data/robots/neura_robotics/neura_robot_description-devel-lara3/lara3/collision/Link2_body.stl"/>
      </geometry>
      <material name="white"/>
    </collision>
  </link>
  <!-- ============================ DOF3 ================================= -->
  <joint name="lara3_joint3" type="revolute">
    <origin rpy="0 0 0" xyz="0 -0.266 0"/>
    <axis xyz="1 0 0"/>
    <limit effort="107" lower="-2.6093" upper="2.6093" velocity="2.6093"/>
    <parent link="lara3_link2"/>
    <child link="lara3_link3"/>
  </joint>
  <link name="lara3_link3">
    <inertial>
      <mass value="3.322"/>
      <origin rpy="0 0 0" xyz="0.020835 -0.041461 1e-05"/>
      <inertia ixx="0.011521" ixy="1e-06" ixz="2e-06" iyy="0.005632" iyz="-0.002225" izz="0.009166"/>
    </inertial>
    <visual>
      <origin rpy="0 0 0" xyz="0 0 0"/>
      <geometry>
        <mesh filename="package://example-robot-data/robots/neura_robotics/neura_robot_description-devel-lara3/lara3/meshes/Link3_body.stl"/>
      </geometry>
      <material name="white"/>
    </visual>
    <visual>
      <origin rpy="0 0 0" xyz="0 0 0"/>
      <geometry>
        <mesh filename="package://example-robot-data/robots/neura_robotics/neura_robot_description-devel-lara3/lara3/meshes/Link3_rings.stl"/>
      </geometry>
      <material name="white"/>
    </visual>
    <collision>
      <origin rpy="0 0 0" xyz="0 0 0"/>
      <geometry>
        <mesh filename="package://example-robot-data/robots/neura_robotics/neura_robot_description-devel-lara3/lara3/collision/Link3_body.stl"/>
      </geometry>
      <material name="white"/>
    </collision>
  </link>
  <!-- ============================ DOF4 ================================= -->
  <joint name="lara3_joint4" type="revolute">
    <origin rpy="0 0 4.89652762781e-12" xyz="0 0 0"/>
    <axis xyz="0 -1 0"/>
    <limit effort="107" lower="-3.14159" upper="3.14159" velocity="3.14159"/>
    <!--<safety_controller k_position="100" k_velocity="2" soft_lower_limit="-2.55948851735" soft_upper_limit="2.55948851735" />-->
    <!-- <dynamics damping="2.5" friction="4.0" /> -->
    <parent link="lara3_link3"/>
    <child link="lara3_link4"/>
  </joint>
  <link name="lara3_link4">
    <inertial>
      <mass value="1.144"/>
      <origin rpy="0 0 0" xyz="0.055318 -0.203673 -3e-06"/>
      <inertia ixx="0.007363" ixy="0.0" ixz="0.002563" iyy="0.008811" iyz="-1e-06" izz="0.002959"/>
    </inertial>
    <visual>
      <origin rpy="0 0 0" xyz="0 0 0"/>
      <geometry>
        <mesh filename="package://example-robot-data/robots/neura_robotics/neura_robot_description-devel-lara3/lara3/meshes/Link4_body.stl"/>
      </geometry>
      <material name="white"/>
    </visual>
    <collision>
      <origin rpy="0 0 0" xyz="0 0 0"/>
      <geometry>
        <mesh filename="package://example-robot-data/robots/neura_robotics/neura_robot_description-devel-lara3/lara3/collision/Link4_body.stl"/>
      </geometry>
      <material name="white"/>
    </collision>
  </link>
  <!-- ============================ DOF5 ================================= -->
  <joint name="lara3_joint5" type="revolute">
    <origin rpy="0 0 -4.89652762781e-12" xyz="0 -0.324 0"/>
    <axis xyz="1 0 0"/>
    <limit effort="36" lower="-3.14159" upper="3.14159" velocity="3.14159"/>
    <!--<safety_controller k_position="100" k_velocity="2" soft_lower_limit="-2.55948851735" soft_upper_limit="2.55948851735" />-->
    <!-- <dynamics damping="5.0" friction="4.0" /> -->
    <parent link="lara3_link4"/>
    <child link="lara3_link5"/>
  </joint>
  <link name="lara3_link5">
    <inertial>
      <mass value="2.494"/>
      <origin rpy="0 0 0" xyz="0.016612 -0.038279 4e-06"/>
      <inertia ixx="0.007591" ixy="0.0" ixz="0.0" iyy="0.003487" iyz="-0.001457" izz="0.005986"/>
    </inertial>
    <visual>
      <origin rpy="0 0 0" xyz="0 0 0"/>
      <geometry>
        <mesh filename="package://example-robot-data/robots/neura_robotics/neura_robot_description-devel-lara3/lara3/meshes/Link5_body.stl"/>
      </geometry>
      <material name="white"/>
    </visual>
    <visual>
      <origin rpy="0 0 0" xyz="0 0 0"/>
      <geometry>
        <mesh filename="package://example-robot-data/robots/neura_robotics/neura_robot_description-devel-lara3/lara3/meshes/Link5_rings.stl"/>
      </geometry>
      <material name="white"/>
    </visual>
    <collision>
      <origin rpy="0 0 0" xyz="0 0 0"/>
      <geometry>
        <mesh filename="package://example-robot-data/robots/neura_robotics/neura_robot_description-devel-lara3/lara3/collision/Link5_body.stl"/>
      </geometry>
      <material name="white"/>
    </collision>
  </link>
  <!-- ============================ DOF6 ================================= -->
  <joint name="lara3_joint6" type="revolute">
    <origin rpy="0 3.14159 0" xyz="0 0 0"/>
    <axis xyz="0 -1 0"/>
    <limit effort="36" lower="-3.14159" upper="3.14159" velocity="3.14159"/>
    <!--<safety_controller k_position="100" k_velocity="2" soft_lower_limit="-4.0" soft_upper_limit="4.0" />-->
    <!-- <dynamics damping="1.25" friction="1.25" /> -->
    <parent link="lara3_link5"/>
    <child link="lara3_link6"/>
  </joint>
  <link name="lara3_link6">
    <inertial>
      <mass value="0.455"/>
      <origin rpy="0 0 0" xyz="0.00709 -0.134603 0.000162"/>
      <inertia ixx="0.0006" ixy="-9e-06" ixz="4e-06" iyy="0.000602" iyz="0.0" izz="0.000605"/>
    </inertial>
    <visual>
      <origin rpy="0 0 0" xyz="0 0 0"/>
      <geometry>
        <mesh filename="package://example-robot-data/robots/neura_robotics/neura_robot_description-devel-lara3/lara3/meshes/Link6_body.stl"/>
      </geometry>
      <material name="white"/>
    </visual>
    <visual>
      <origin rpy="0 0 0" xyz="0 0 0"/>
      <geometry>
        <mesh filename="package://example-robot-data/robots/neura_robotics/neura_robot_description-devel-lara3/lara3/meshes/Link6_connector.stl"/>
      </geometry>
      <material name="white"/>
    </visual>
    <collision>
      <origin rpy="0 0 0" xyz="0 0 0"/>
      <geometry>
        <mesh filename="package://example-robot-data/robots/neura_robotics/neura_robot_description-devel-lara3/lara3/collision/Link6_body.stl"/>
      </geometry>
      <material name="white"/>
    </collision>
  </link>
  <!-- ============================ Flange ================================= -->
  <link name="lara3_flange"/>
  <joint name="lara3_link6_to_flange" type="fixed">
    <origin rpy="1.57079632679 1.57079632679 0" xyz="0 -0.1655 0"/>
    <parent link="lara3_link6"/>
    <child link="lara3_flange"/>
  </joint>
  <link name="world"/>
  <joint name="world_joint" type="fixed">
    <parent link="world"/>
    <child link="lara3_root_link"/>
    <origin rpy="0.0 0.0 0.0" xyz="0.0 0.0 0.0"/>
  </joint>
</robot>

