<?xml version="1.0" ?>
<!-- =================================================================================== -->
<!-- |    This document was autogenerated by xacro from pzv_64.urdf.xacro              | -->
<!-- |    EDITING THIS FILE BY HAND IS NOT RECOMMENDED                                 | -->
<!-- =================================================================================== -->
<robot name="pzv_64">
  <!--degrees to radians-->
  <!-- xacro:pzv_64_base_link prefix="" meshType="dae" / -->
  <!-- xacro:pzv_64_fingers_link prefix="" meshType="dae" / -->
  <!-- xacro:pzv_64_transmission prefix=""  / -->
  <!-- links -->
  <link name="pzv_base_link">
    <inertial>
      <origin rpy="0 0 0" xyz="0.00042957 -0.00042711 0.019104"/>
      <mass value="0.1209"/>
      <inertia ixx="4.7826E-05" ixy="-9.1279E-07" ixz="1.0214E-07" iyy="4.6015E-05" iyz="-5.5318E-08" izz="7.477E-05"/>
    </inertial>
    <visual>
      <origin rpy="0 0 0" xyz="0 0 0"/>
      <geometry>
        <mesh filename="package://pzv_64_description/meshes/pvz_base.dae"/>
      </geometry>
      <material name="">
        <color rgba="0.50196 0.50196 0 1"/>
      </material>
    </visual>
    <collision>
      <origin rpy="0 0 0" xyz="0 0 0"/>
      <geometry>
        <mesh filename="package://pzv_64_description/meshes/pvz_base.dae"/>
      </geometry>
    </collision>
  </link>
  <link name="pzv_trans_1">
    <inertial>
      <origin rpy="0 0 0" xyz="1.4929E-10 -0.013586 -0.00041877"/>
      <mass value="0.0038281"/>
      <inertia ixx="2.8349E-07" ixy="3.8104E-17" ixz="1.0125E-14" iyy="9.4836E-08" iyz="-8.3614E-09" izz="2.9125E-07"/>
    </inertial>
    <visual>
      <origin rpy="0 0 1.570796" xyz="0.0013 -0.027 -0.00645"/>
      <geometry>
        <mesh filename="package://pzv_64_description/meshes/pvz_trans.dae"/>
      </geometry>
      <material name="">
        <color rgba="0.066667 0.066667 0.066667 1"/>
      </material>
    </visual>
    <collision>
      <origin rpy="0 0 1.570796" xyz="0.0013 -0.027 -0.00645"/>
      <geometry>
        <mesh filename="package://pzv_64_description/meshes/pvz_trans.dae"/>
      </geometry>
    </collision>
  </link>
  <link name="pzv_trans_2">
    <inertial>
      <origin rpy="0 0 0" xyz="1.4929E-10 -0.013586 -0.00041877"/>
      <mass value="0.0038281"/>
      <inertia ixx="2.8349E-07" ixy="3.8104E-17" ixz="1.0125E-14" iyy="9.4836E-08" iyz="-8.3614E-09" izz="2.9125E-07"/>
    </inertial>
    <visual>
      <origin rpy="0 0 1.570796" xyz="0.0002 -0.027 -0.00645"/>
      <geometry>
        <mesh filename="package://pzv_64_description/meshes/pvz_trans.dae"/>
      </geometry>
      <material name="">
        <color rgba="0.066667 0.066667 0.066667 1"/>
      </material>
    </visual>
    <collision>
      <origin rpy="0 0 1.570796" xyz="0.0002 -0.027 -0.00645"/>
      <geometry>
        <mesh filename="package://pzv_64_description/meshes/pvz_trans.dae"/>
      </geometry>
    </collision>
  </link>
  <link name="pzv_trans_3">
    <inertial>
      <origin rpy="0 0 0" xyz="1.4929E-10 -0.013586 -0.00041877"/>
      <mass value="0.0038281"/>
      <inertia ixx="2.8349E-07" ixy="3.8104E-17" ixz="1.0125E-14" iyy="9.4836E-08" iyz="-8.3614E-09" izz="2.9125E-07"/>
    </inertial>
    <visual>
      <origin rpy="0 0 1.570796" xyz="-0.0013 -0.027 -0.00645"/>
      <geometry>
        <mesh filename="package://pzv_64_description/meshes/pvz_trans.dae"/>
      </geometry>
      <material name="">
        <color rgba="0.066667 0.066667 0.066667 1"/>
      </material>
    </visual>
    <collision>
      <origin rpy="0 0 1.570796" xyz="-0.0013 -0.027 -0.00645"/>
      <geometry>
        <mesh filename="package://pzv_64_description/meshes/pvz_trans.dae"/>
      </geometry>
    </collision>
  </link>
  <link name="pzv_trans_4">
    <inertial>
      <origin rpy="0 0 0" xyz="0 0 0"/>
      <mass value="0"/>
      <inertia ixx="0" ixy="0" ixz="0" iyy="0" iyz="0" izz="0"/>
    </inertial>
    <visual>
      <origin rpy="0 0 1.570796" xyz="-0.0002 -0.027 -0.00645"/>
      <geometry>
        <mesh filename="package://pzv_64_description/meshes/pvz_trans.dae"/>
      </geometry>
      <material name="">
        <color rgba="1 1 1 1"/>
      </material>
    </visual>
    <collision>
      <origin rpy="0 0 1.570796" xyz="-0.0002 -0.027 -0.00645"/>
      <geometry>
        <mesh filename="package://pzv_64_description/meshes/pvz_trans.dae"/>
      </geometry>
    </collision>
  </link>
  <joint name="pzv_prismatic_1" type="prismatic">
    <origin rpy="0 0 2.3562" xyz="-0.025725 -0.027563 0.034766"/>
    <parent link="pzv_base_link"/>
    <child link="pzv_trans_1"/>
    <axis xyz="0 1 0"/>
    <limit effort="300" lower="-0.009" upper="0.0045" velocity="1"/>
    <dynamics damping="0.3" friction="0.2"/>
  </joint>
  <joint name="pzv_prismatic_2" type="prismatic">
    <origin rpy="0 0 -2.3562" xyz="0.026854 -0.026563 0.034766"/>
    <parent link="pzv_base_link"/>
    <child link="pzv_trans_2"/>
    <axis xyz="0 1 0"/>
    <limit effort="300" lower="-0.009" upper="0.0045" velocity="1"/>
    <mimic joint="pzv_prismatic_1" multiplier="1" offset="0"/>
    <dynamics damping="0.3" friction="0.2"/>
  </joint>
  <joint name="pzv_prismatic_3" type="prismatic">
    <origin rpy="0 0 -0.7854" xyz="0.027554 0.0257016 0.034766"/>
    <parent link="pzv_base_link"/>
    <child link="pzv_trans_3"/>
    <axis xyz="0 1 0"/>
    <limit effort="300" lower="-0.009" upper="0.0045" velocity="1"/>
    <mimic joint="pzv_prismatic_1" multiplier="1" offset="0"/>
    <dynamics damping="0.3" friction="0.2"/>
  </joint>
  <joint name="pzv_prismatic_4" type="prismatic">
    <origin rpy="0 0 0.7854" xyz="-0.026725 0.027016 0.034766"/>
    <parent link="pzv_base_link"/>
    <child link="pzv_trans_4"/>
    <axis xyz="0 1 0"/>
    <limit effort="300" lower="-0.009" upper="0.0045" velocity="1"/>
    <mimic joint="pzv_prismatic_1" multiplier="1" offset="0"/>
    <dynamics damping="0.3" friction="0.2"/>
  </joint>
  <!-- links -->
  <link name="pzv_finger_1">
    <inertial>
      <origin rpy="0 0 0" xyz="9.074E-06 -0.011739 0.03368"/>
      <mass value="0.0098228"/>
      <inertia ixx="2.9703E-06" ixy="-1.6622E-10" ixz="3.1061E-09" iyy="2.7246E-06" iyz="2.3497E-07" izz="4.7539E-07"/>
    </inertial>
    <visual>
      <origin rpy="0 0 0" xyz="0.0013 -0.0187 0.00645"/>
      <geometry>
        <mesh filename="package://pzv_64_description/meshes/pvz_finger.dae"/>
      </geometry>
      <material name="">
        <color rgba="0.79216 0.81961 0.93333 1"/>
      </material>
    </visual>
    <collision>
      <origin rpy="0 0 0" xyz="0.0013 -0.0187 0.00645"/>
      <geometry>
        <mesh filename="package://pzv_64_description/meshes/pvz_finger.dae"/>
      </geometry>
    </collision>
  </link>
  <link name="pzv_finger_2">
    <inertial>
      <origin rpy="0 0 0" xyz="9.074E-06 -0.011739 0.03368"/>
      <mass value="0.0098228"/>
      <inertia ixx="2.9703E-06" ixy="-1.6622E-10" ixz="3.1061E-09" iyy="2.7246E-06" iyz="2.3497E-07" izz="4.7539E-07"/>
    </inertial>
    <visual>
      <origin rpy="0 0 0" xyz="0.0002 -0.0187 0.00645"/>
      <geometry>
        <mesh filename="package://pzv_64_description/meshes/pvz_finger.dae"/>
      </geometry>
      <material name="">
        <color rgba="0.79216 0.81961 0.93333 1"/>
      </material>
    </visual>
    <collision>
      <origin rpy="0 0 0" xyz="0.0002 -0.0187 0.00645"/>
      <geometry>
        <mesh filename="package://pzv_64_description/meshes/pvz_finger.dae"/>
      </geometry>
    </collision>
  </link>
  <link name="pzv_finger_3">
    <inertial>
      <origin rpy="0 0 0" xyz="9.074E-06 -0.011739 0.03368"/>
      <mass value="0.0098228"/>
      <inertia ixx="2.9703E-06" ixy="-1.6622E-10" ixz="3.1061E-09" iyy="2.7246E-06" iyz="2.3497E-07" izz="4.7539E-07"/>
    </inertial>
    <visual>
      <origin rpy="0 0 0" xyz="-0.0013 -0.0187 0.00645"/>
      <geometry>
        <mesh filename="package://pzv_64_description/meshes/pvz_finger.dae"/>
      </geometry>
      <material name="">
        <color rgba="0.79216 0.81961 0.93333 1"/>
      </material>
    </visual>
    <collision>
      <origin rpy="0 0 0" xyz="-0.0013 -0.0187 0.00645"/>
      <geometry>
        <mesh filename="package://pzv_64_description/meshes/pvz_finger.dae"/>
      </geometry>
    </collision>
  </link>
  <link name="pzv_finger_4">
    <inertial>
      <origin rpy="0 0 0" xyz="9.074E-06 -0.011739 0.03368"/>
      <mass value="0.0098228"/>
      <inertia ixx="2.9703E-06" ixy="-1.6622E-10" ixz="3.1061E-09" iyy="2.7246E-06" iyz="2.3497E-07" izz="4.7539E-07"/>
    </inertial>
    <visual>
      <origin rpy="0 0 0" xyz="-0.0002 -0.0187 0.00645"/>
      <geometry>
        <mesh filename="package://pzv_64_description/meshes/pvz_finger.dae"/>
      </geometry>
      <material name="">
        <color rgba="0.79216 0.81961 0.93333 1"/>
      </material>
    </visual>
    <collision>
      <origin rpy="0 0 0" xyz="-0.0002 -0.0187 0.00645"/>
      <geometry>
        <mesh filename="package://pzv_64_description/meshes/pvz_finger.dae"/>
      </geometry>
    </collision>
  </link>
  <transmission name="trans_prismatic_joint_translational_1_effort">
    <type>transmission_interface/SimpleTransmission</type>
    <joint name="pzv_prismatic_1">
      <hardwareInterface>hardware_interface/EffortJointInterface</hardwareInterface>
    </joint>
    <actuator name="prismatic_joint_translational_1_motor_effort">
      <hardwareInterface>hardware_interface/EffortJointInterface</hardwareInterface>
      <mechanicalReduction>1</mechanicalReduction>
    </actuator>
  </transmission>
  <gazebo>
    <plugin filename="libroboticsgroup_upatras_gazebo_mimic_joint_plugin.so" name="translational_2">
      <joint>pzv_prismatic_1</joint>
      <mimicJoint>pzv_prismatic_2</mimicJoint>
      <multiplier>1</multiplier>
      <offset>0</offset>
    </plugin>
  </gazebo>
  <gazebo>
    <plugin filename="libroboticsgroup_upatras_gazebo_mimic_joint_plugin.so" name="translational_3">
      <joint>pzv_prismatic_1</joint>
      <mimicJoint>pzv_prismatic_3</mimicJoint>
      <multiplier>1</multiplier>
      <offset>0</offset>
    </plugin>
  </gazebo>
  <gazebo>
    <plugin filename="libroboticsgroup_upatras_gazebo_mimic_joint_plugin.so" name="translational_4">
      <joint>pzv_prismatic_1</joint>
      <mimicJoint>pzv_prismatic_4</mimicJoint>
      <multiplier>1</multiplier>
      <offset>0</offset>
    </plugin>
  </gazebo>
  <!-- links -->
  <!--link name="world" /-->
  <!--
        <joint name="fixed" type="fixed">
            <parent link="world" />
            <child link="${prefix}base_link" />
        </joint>
-->
  <joint name="pzv_finger_1" type="fixed">
    <origin rpy="0 0 0" xyz="0 0 0.00"/>
    <parent link="pzv_trans_1"/>
    <child link="pzv_finger_1"/>
    <axis xyz="0 0 0"/>
  </joint>
  <joint name="pzv_finger_2" type="fixed">
    <origin rpy="0 0 0" xyz="0 0 0.00"/>
    <parent link="pzv_trans_2"/>
    <child link="pzv_finger_2"/>
    <axis xyz="0 0 0"/>
  </joint>
  <joint name="pzv_finger_3" type="fixed">
    <origin rpy="0 0 0" xyz="0 0 0.00"/>
    <parent link="pzv_trans_3"/>
    <child link="pzv_finger_3"/>
    <axis xyz="0 0 0"/>
  </joint>
  <joint name="pzv_finger_4" type="fixed">
    <origin rpy="0 0 0" xyz="0 0 0.00"/>
    <parent link="pzv_trans_4"/>
    <child link="pzv_finger_4"/>
    <axis xyz="0 0 0"/>
  </joint>
</robot>

