<?xml version="1.0" ?>
<!-- =================================================================================== -->
<!-- |    This document was autogenerated by xacro from src/schunk_description/egu_description/urdf/egu_50.urdf.xacro | -->
<!-- |    EDITING THIS FILE BY HAND IS NOT RECOMMENDED                                 | -->
<!-- =================================================================================== -->
<robot name="egu_50">
  <!--degrees to radians-->
  <!-- colors -->
  <material name="light_blue_1">
    <color rgba="0.79216 0.81961 0.93333 1"/>
  </material>
  <material name="light_grey">
    <color rgba="0.69412 0.75294 0.77255 1"/>
  </material>
  <!-- xacro:egu_50_base_link prefix="" meshType="dae" / -->
  <!-- colors -->
  <material name="light_blue">
    <color rgba="0.79216 0.81961 0.93333 1"/>
  </material>
  <material name="grey">
    <color rgba="0.68627 0.68627 0.68627 1"/>
  </material>
  <!-- xacro:egu_50_fingers_link prefix="" meshType="dae" / -->
  <!-- xacro:egu_50_fingers_link prefix="" meshType="dae" / -->
  <!-- links -->
  <link name="egu_50_base_link">
    <inertial>
      <origin rpy="0 0 0" xyz="4.3604E-07 0.00037988 0.038749"/>
      <mass value="1.4423"/>
      <inertia ixx="0.0011497" ixy="-1.8423E-07" ixz="-9.465E-09" iyy="0.00061843" iyz="9.7336E-07" izz="0.0011032"/>
    </inertial>
    <visual>
      <origin rpy="0 0 0" xyz="0 0 0"/>
      <geometry>
        <mesh filename="package://example-robot-data/end_effectors/schunk/egu_description/meshes/base_link.dae"/>
      </geometry>
      <material name="light_blue_1"/>
    </visual>
    <collision>
      <origin rpy="0 0 0" xyz="0 0 0"/>
      <geometry>
        <mesh filename="package://example-robot-data/end_effectors/schunk/egu_description/meshes/base_link.dae"/>
      </geometry>
    </collision>
  </link>
  <link name="egu_50_symbol_1_left">
    <inertial>
      <origin rpy="0 0 0" xyz="-0.00014475 -7.7141E-05 -1.6517E-07"/>
      <mass value="0.00028259"/>
      <inertia ixx="1.9364E-08" ixy="-1.2932E-12" ixz="-2.7689E-15" iyy="1.2696E-09" iyz="-1.5694E-12" izz="1.8096E-08"/>
    </inertial>
    <visual>
      <origin rpy="0 0 0" xyz="0 0 0"/>
      <geometry>
        <mesh filename="package://example-robot-data/end_effectors/schunk/egu_description/meshes/symbol_1_left.dae"/>
      </geometry>
      <material name="light_blue_1"/>
    </visual>
    <collision>
      <origin rpy="0 0 0" xyz="0 0 0"/>
      <geometry>
        <mesh filename="package://example-robot-data/end_effectors/schunk/egu_description/meshes/symbol_1_left.dae"/>
      </geometry>
    </collision>
  </link>
  <link name="egu_50_symbo_1_right">
    <inertial>
      <origin rpy="0 0 0" xyz="0.00014475 7.7141E-05 -1.6517E-07"/>
      <mass value="0.00028259"/>
      <inertia ixx="1.9364E-08" ixy="-1.2932E-12" ixz="2.7689E-15" iyy="1.2696E-09" iyz="1.5694E-12" izz="1.8096E-08"/>
    </inertial>
    <visual>
      <origin rpy="0 0 0" xyz="0 0 0"/>
      <geometry>
        <mesh filename="package://example-robot-data/end_effectors/schunk/egu_description/meshes/symbol_1_right.dae"/>
      </geometry>
      <material name="light_blue_1"/>
    </visual>
    <collision>
      <origin rpy="0 0 0" xyz="0 0 0"/>
      <geometry>
        <mesh filename="package://example-robot-data/end_effectors/schunk/egu_description/meshes/symbol_1_right.dae"/>
      </geometry>
    </collision>
  </link>
  <link name="egu_50_translational_left">
    <inertial>
      <origin rpy="0 0 0" xyz="-1.4263E-11 -1.7621E-09 -0.0072452"/>
      <mass value="0.023586"/>
      <inertia ixx="4.5433E-06" ixy="-1.0067E-14" ixz="3.9379E-16" iyy="3.0604E-07" iyz="9.2402E-14" izz="4.5738E-06"/>
    </inertial>
    <visual>
      <origin rpy="0 0 0" xyz="0 0 0"/>
      <geometry>
        <mesh filename="package://example-robot-data/end_effectors/schunk/egu_description/meshes/translational_left.dae"/>
      </geometry>
      <material name="light_grey"/>
    </visual>
    <collision>
      <origin rpy="0 0 0" xyz="0 0 0"/>
      <geometry>
        <mesh filename="package://example-robot-data/end_effectors/schunk/egu_description/meshes/translational_left.dae"/>
      </geometry>
    </collision>
  </link>
  <link name="egu_50_translational_right">
    <inertial>
      <origin rpy="0 0 0" xyz="1.4263E-11 1.7621E-09 -0.0072452"/>
      <mass value="0.023586"/>
      <inertia ixx="4.5433E-06" ixy="-1.0067E-14" ixz="-3.9379E-16" iyy="3.0604E-07" iyz="-9.2402E-14" izz="4.5738E-06"/>
    </inertial>
    <visual>
      <origin rpy="0 0 0" xyz="0 0 0"/>
      <geometry>
        <mesh filename="package://example-robot-data/end_effectors/schunk/egu_description/meshes/translational_right.dae"/>
      </geometry>
      <material name="light_grey"/>
    </visual>
    <collision>
      <origin rpy="0 0 0" xyz="0 0 0"/>
      <geometry>
        <mesh filename="package://example-robot-data/end_effectors/schunk/egu_description/meshes/translational_right.dae"/>
      </geometry>
    </collision>
  </link>
  <!-- joints -->
  <joint name="egu_50_fixed_joint_symbol_1_left" type="fixed">
    <origin rpy="0 0 0" xyz="0 0.0353 0.0701"/>
    <parent link="egu_50_base_link"/>
    <child link="egu_50_symbol_1_left"/>
    <axis xyz="0 0 0"/>
  </joint>
  <joint name="egu_50_fixed_joint_symbol_1_right" type="fixed">
    <origin rpy="0 0 0" xyz="0 -0.0353 0.0701"/>
    <parent link="egu_50_base_link"/>
    <child link="egu_50_symbo_1_right"/>
    <axis xyz="0 0 0"/>
  </joint>
  <joint name="egu_50_prismatic_1" type="prismatic">
    <origin rpy="0 0 0" xyz="-0.01258 0.01265 0.083"/>
    <parent link="egu_50_base_link"/>
    <child link="egu_50_translational_left"/>
    <axis xyz="1 0 0"/>
    <limit effort="300" lower="-0.012" upper="0.039" velocity="0.11"/>
    <dynamics damping="0.3" friction="0.2"/>
  </joint>
  <joint name="egu_50_prismatic_2" type="prismatic">
    <origin rpy="0 0 0" xyz="0.01258 -0.01265 0.083"/>
    <parent link="egu_50_base_link"/>
    <child link="egu_50_translational_right"/>
    <axis xyz="1 0 0"/>
    <limit effort="300" lower="-0.039" upper="0.012" velocity="0.11"/>
    <mimic joint="egu_50_prismatic_1" multiplier="-1" offset="0"/>
    <dynamics damping="0.3" friction="0.2"/>
  </joint>
  <!-- links -->
  <link name="egu_50_base_link_left">
    <inertial>
      <origin rpy="0 0 0" xyz="0.0047644 -0.022233 -0.0049679"/>
      <mass value="0.011214"/>
      <inertia ixx="1.0648E-06" ixy="2.7782E-07" ixz="-1.0154E-09" iyy="3.0857E-07" iyz="2.0857E-09" izz="1.2766E-06"/>
    </inertial>
    <visual>
      <origin rpy="0 0 0" xyz="0 0 0"/>
      <geometry>
        <mesh filename="package://example-robot-data/end_effectors/schunk/egu_description/meshes/gripper_base_link_left.dae"/>
      </geometry>
      <material name="light_blue"/>
    </visual>
    <collision>
      <origin rpy="0 0 0" xyz="0 0 0"/>
      <geometry>
        <mesh filename="package://example-robot-data/end_effectors/schunk/egu_description/meshes/gripper_base_link_left.dae"/>
      </geometry>
    </collision>
  </link>
  <link name="egu_50_base_link_right">
    <inertial>
      <origin rpy="0 0 0" xyz="-0.0047644 0.022233 -0.0049679"/>
      <mass value="0.011214"/>
      <inertia ixx="1.0648E-06" ixy="2.7782E-07" ixz="1.0154E-09" iyy="3.0857E-07" iyz="-2.0857E-09" izz="1.2766E-06"/>
    </inertial>
    <visual>
      <origin rpy="0 0 0" xyz="0 0 0"/>
      <geometry>
        <mesh filename="package://example-robot-data/end_effectors/schunk/egu_description/meshes/gripper_base_link_right.dae"/>
      </geometry>
      <material name="light_blue"/>
    </visual>
    <collision>
      <origin rpy="0 0 0" xyz="0 0 0"/>
      <geometry>
        <mesh filename="package://example-robot-data/end_effectors/schunk/egu_description/meshes/gripper_base_link_right.dae"/>
      </geometry>
    </collision>
  </link>
  <link name="egu_50_finger_down">
    <inertial>
      <origin rpy="0 0 0" xyz="-3.0212E-05 -0.0036302 0.036294"/>
      <mass value="0.028"/>
      <inertia ixx="8.0228E-06" ixy="-1.3517E-09" ixz="-1.4745E-08" iyy="7.1741E-06" iyz="-1.1797E-06" izz="1.4075E-06"/>
    </inertial>
    <visual>
      <origin rpy="0 0 0" xyz="0 0 0"/>
      <geometry>
        <mesh filename="package://example-robot-data/end_effectors/schunk/egu_description/meshes/gripper_finger_down.dae"/>
      </geometry>
      <material name="light_blue"/>
    </visual>
    <collision>
      <origin rpy="0 0 0" xyz="0 0 0"/>
      <geometry>
        <mesh filename="package://example-robot-data/end_effectors/schunk/egu_description/meshes/gripper_finger_down.dae"/>
      </geometry>
    </collision>
  </link>
  <link name="egu_50_finger_up">
    <inertial>
      <origin rpy="0 0 0" xyz="3.0212E-05 0.0036302 0.036294"/>
      <mass value="0.028"/>
      <inertia ixx="8.0228E-06" ixy="-1.3517E-09" ixz="1.4745E-08" iyy="7.1741E-06" iyz="1.1797E-06" izz="1.4075E-06"/>
    </inertial>
    <visual>
      <origin rpy="0 0 0" xyz="0 0 0"/>
      <geometry>
        <mesh filename="package://example-robot-data/end_effectors/schunk/egu_description/meshes/gripper_finger_up.dae"/>
      </geometry>
      <material name="light_blue"/>
    </visual>
    <collision>
      <origin rpy="0 0 0" xyz="0 0 0"/>
      <geometry>
        <mesh filename="package://example-robot-data/end_effectors/schunk/egu_description/meshes/gripper_finger_up.dae"/>
      </geometry>
    </collision>
  </link>
  <link name="egu_50_symbol_2_left">
    <inertial>
      <origin rpy="0 0 0" xyz="-0.00014622 -3.5571E-05 -4.593E-08"/>
      <mass value="5E-05"/>
      <inertia ixx="6.5907E-10" ixy="-1.2575E-13" ixz="-1.6238E-16" iyy="7.8343E-11" iyz="-6.746E-14" izz="5.8113E-10"/>
    </inertial>
    <visual>
      <origin rpy="0 0 0" xyz="0 0 0"/>
      <geometry>
        <mesh filename="package://example-robot-data/end_effectors/schunk/egu_description/meshes/symbol_2_left.dae"/>
      </geometry>
      <material name="light_blue"/>
    </visual>
    <collision>
      <origin rpy="0 0 0" xyz="0 0 0"/>
      <geometry>
        <mesh filename="package://example-robot-data/end_effectors/schunk/egu_description/meshes/symbol_2_left.dae"/>
      </geometry>
    </collision>
  </link>
  <link name="egu_50_symbol_2_right">
    <inertial>
      <origin rpy="0 0 0" xyz="0.00014622 3.5571E-05 -4.593E-08"/>
      <mass value="5E-05"/>
      <inertia ixx="6.5907E-10" ixy="-1.2575E-13" ixz="1.6238E-16" iyy="7.8343E-11" iyz="6.746E-14" izz="5.8113E-10"/>
    </inertial>
    <visual>
      <origin rpy="0 0 0" xyz="0 0 0"/>
      <geometry>
        <mesh filename="package://example-robot-data/end_effectors/schunk/egu_description/meshes/symbol_2_right.dae"/>
      </geometry>
      <material name="light_blue"/>
    </visual>
    <collision>
      <origin rpy="0 0 0" xyz="0 0 0"/>
      <geometry>
        <mesh filename="package://example-robot-data/end_effectors/schunk/egu_description/meshes/symbol_2_right.dae"/>
      </geometry>
    </collision>
  </link>
  <link name="egu_50_screw_1">
    <inertial>
      <origin rpy="0 0 0" xyz="-5.9458E-20 -6.9389E-18 -0.0040161"/>
      <mass value="0.00059"/>
      <inertia ixx="1.2809E-08" ixy="3.2834E-26" ixz="2.1005E-25" iyy="1.2809E-08" iyz="2.3683E-25" izz="1.3113E-09"/>
    </inertial>
    <visual>
      <origin rpy="0 0 0" xyz="0 0 0"/>
      <geometry>
        <mesh filename="package://example-robot-data/end_effectors/schunk/egu_description/meshes/screw_1.dae"/>
      </geometry>
      <material name="grey"/>
    </visual>
    <collision>
      <origin rpy="0 0 0" xyz="0 0 0"/>
      <geometry>
        <mesh filename="package://example-robot-data/end_effectors/schunk/egu_description/meshes/screw_1.dae"/>
      </geometry>
    </collision>
  </link>
  <link name="egu_50_screw_2">
    <inertial>
      <origin rpy="0 0 0" xyz="-5.8248E-20 0 -0.0040161"/>
      <mass value="0.00059"/>
      <inertia ixx="1.2809E-08" ixy="3.2834E-26" ixz="2.1401E-25" iyy="1.2809E-08" iyz="2.3533E-25" izz="1.3113E-09"/>
    </inertial>
    <visual>
      <origin rpy="0 0 0" xyz="0 0 0"/>
      <geometry>
        <mesh filename="package://example-robot-data/end_effectors/schunk/egu_description/meshes/screw_2.dae"/>
      </geometry>
      <material name="grey"/>
    </visual>
    <collision>
      <origin rpy="0 0 0" xyz="0 0 0"/>
      <geometry>
        <mesh filename="package://example-robot-data/end_effectors/schunk/egu_description/meshes/screw_2.dae"/>
      </geometry>
    </collision>
  </link>
  <link name="egu_50_screw_3">
    <inertial>
      <origin rpy="0 0 0" xyz="5.9458E-20 0 -0.0040161"/>
      <mass value="0.00059"/>
      <inertia ixx="1.2809E-08" ixy="3.2834E-26" ixz="-2.1005E-25" iyy="1.2809E-08" iyz="-2.3683E-25" izz="1.3113E-09"/>
    </inertial>
    <visual>
      <origin rpy="0 0 0" xyz="0 0 0"/>
      <geometry>
        <mesh filename="package://example-robot-data/end_effectors/schunk/egu_description/meshes/screw_3.dae"/>
      </geometry>
      <material name="grey"/>
    </visual>
    <collision>
      <origin rpy="0 0 0" xyz="0 0 0"/>
      <geometry>
        <mesh filename="package://example-robot-data/end_effectors/schunk/egu_description/meshes/screw_3.dae"/>
      </geometry>
    </collision>
  </link>
  <link name="egu_50_screw_4">
    <inertial>
      <origin rpy="0 0 0" xyz="5.9458E-20 6.9389E-18 -0.0040161"/>
      <mass value="0.00059"/>
      <inertia ixx="1.2809E-08" ixy="3.2834E-26" ixz="-2.1005E-25" iyy="1.2809E-08" iyz="-2.3683E-25" izz="1.3113E-09"/>
    </inertial>
    <visual>
      <origin rpy="0 0 0" xyz="0 0 0"/>
      <geometry>
        <mesh filename="package://example-robot-data/end_effectors/schunk/egu_description/meshes/screw_4.dae"/>
      </geometry>
      <material name="grey"/>
    </visual>
    <collision>
      <origin rpy="0 0 0" xyz="0 0 0"/>
      <geometry>
        <mesh filename="package://example-robot-data/end_effectors/schunk/egu_description/meshes/screw_4.dae"/>
      </geometry>
    </collision>
  </link>
  <!-- joints -->
  <joint name="fixed_joint_egu_50_screw_2" type="fixed">
    <origin rpy="0 0 0" xyz="0.025 0.01258 0.00800000000000001"/>
    <parent link="egu_50_base_link_right"/>
    <child link="egu_50_screw_2"/>
    <axis xyz="0 0 0"/>
  </joint>
  <joint name="fixed_joint_egu_50_screw_1" type="fixed">
    <origin rpy="0 0 0" xyz="0.038 0.01258 0.00800000000000001"/>
    <parent link="egu_50_base_link_right"/>
    <child link="egu_50_screw_1"/>
    <axis xyz="0 0 0"/>
  </joint>
  <joint name="fixed_joint_egu_50_screw_3" type="fixed">
    <origin rpy="0 0 0" xyz="-0.025 -0.01258 0.00800000000000001"/>
    <parent link="egu_50_base_link_left"/>
    <child link="egu_50_screw_3"/>
    <axis xyz="0 0 0"/>
  </joint>
  <joint name="fixed_joint_egu_50_screw_4" type="fixed">
    <origin rpy="0 0 0" xyz="-0.038 -0.01258 0.00800000000000001"/>
    <parent link="egu_50_base_link_left"/>
    <child link="egu_50_screw_4"/>
    <axis xyz="0 0 0"/>
  </joint>
  <joint name="fixed_joint_finger_up" type="fixed">
    <origin rpy="0 0 0" xyz="0 0 -0.00800000000000001"/>
    <parent link="egu_50_screw_2"/>
    <child link="egu_50_finger_up"/>
    <axis xyz="0 0 0"/>
  </joint>
  <joint name="fixed_joint_gripper_finger_down" type="fixed">
    <origin rpy="0 0 0" xyz="0.013 0 -0.00800000000000001"/>
    <parent link="egu_50_screw_4"/>
    <child link="egu_50_finger_down"/>
    <axis xyz="0 0 0"/>
  </joint>
  <joint name="fixed_joint_symbol_2_left" type="fixed">
    <origin rpy="0 0 0" xyz="0.0065 0.00575 0.005"/>
    <parent link="egu_50_finger_up"/>
    <child link="egu_50_symbol_2_left"/>
    <axis xyz="0 0 0"/>
  </joint>
  <joint name="fixed_joint_symbol_2_right" type="fixed">
    <origin rpy="0 0 0" xyz="-0.0065 -0.00575 0.005"/>
    <parent link="egu_50_finger_down"/>
    <child link="egu_50_symbol_2_right"/>
    <axis xyz="0 0 0"/>
  </joint>
  <gazebo reference="egu_50_finger_down">
    <kp>1000000.0</kp>
    <kd>1.0</kd>
    <mu1>1.0</mu1>
    <mu2>1.0</mu2>
    <minDepth>0.001</minDepth>
  </gazebo>
  <gazebo reference="egu_50_finger_up">
    <kp>1000000.0</kp>
    <kd>1.0</kd>
    <mu1>1.0</mu1>
    <mu2>1.0</mu2>
    <minDepth>0.001</minDepth>
  </gazebo>
  <transmission name="trans_prismatic_joint_translational_1_effort">
    <type>transmission_interface/SimpleTransmission</type>
    <joint name="egu_50_prismatic_1">
      <hardwareInterface>hardware_interface/EffortJointInterface</hardwareInterface>
    </joint>
    <actuator name="prismatic_joint_translational_1_motor_effort">
      <hardwareInterface>hardware_interface/EffortJointInterface</hardwareInterface>
      <mechanicalReduction>1</mechanicalReduction>
    </actuator>
  </transmission>
  <gazebo>
    <plugin filename="libroboticsgroup_upatras_gazebo_mimic_joint_plugin.so" name="translational_2">
      <joint>egu_50_prismatic_1</joint>
      <mimicJoint>egu_50_prismatic_2</mimicJoint>
      <multiplier>-1</multiplier>
      <offset>0</offset>
    </plugin>
  </gazebo>
  <!-- links -->
  <!--link name="world" /-->
  <!--
        <joint name="fixed" type="fixed">
            <parent link="world" />
            <child link="${prefix}base_link" />
        </joint>
-->
  <!-- <joint name="fixed_joint_gripper_base_link_right" type="fixed">
          <origin xyz="0.018 0 0.01" rpy="1.5708 0 -1.5708" />
          <parent link="${prefix_1}_translational_right" />
          <child link="${prefix_2}_base_link_right" />
          <axis xyz="0 0 0" />
        </joint>

        <joint name="fixed_joint_gripper_base_link_left" type="fixed">
          <origin xyz="-0.018 0 0.01" rpy="1.5708 0 1.5708" />
          <parent link="${prefix_1}_translational_left" />
          <child link="${prefix_2}_base_link_left" />
          <axis xyz="0 0 0" />
        </joint> -->
  <joint name="fixed_joint_gripper_base_link_right" type="fixed">
    <origin rpy="0 0 0" xyz="0.018 0 0.01"/>
    <parent link="egu_50_translational_right"/>
    <child link="egu_50_base_link_right"/>
    <axis xyz="0 0 0"/>
  </joint>
  <joint name="fixed_joint_gripper_base_link_left" type="fixed">
    <origin rpy="0 0 0" xyz="-0.018 0 0.01"/>
    <parent link="egu_50_translational_left"/>
    <child link="egu_50_base_link_left"/>
    <axis xyz="0 0 0"/>
  </joint>
</robot>

