<?xml version="1.0"?>
<robot xmlns:xacro="http://www.ros.org/wiki/xacro">

  <!-- colors -->
  <material name="light_blue_1">
    <color rgba="0.79216 0.81961 0.93333 1" />
  </material>
  <material name="light_grey">
    <color rgba="0.69412 0.75294 0.77255 1" />
  </material>

  <xacro:macro name="egu_50_base_link" params="prefix meshType">
    <!-- links -->
    <link name="${prefix}base_link">
      <inertial>
        <origin xyz="4.3604E-07 0.00037988 0.038749" rpy="0 0 0" />
        <mass value="1.4423" />
        <inertia
          ixx="0.0011497"
          ixy="-1.8423E-07"
          ixz="-9.465E-09"
          iyy="0.00061843"
          iyz="9.7336E-07"
          izz="0.0011032" />
      </inertial>
      <visual>
        <origin
          xyz="0 0 0"
          rpy="0 0 0" />
        <geometry>
          <mesh
            filename="package://egu_description/meshes/base_link.${meshType}" />
        </geometry>
        <material name="light_blue_1" />
      </visual>
      <collision>
        <origin
          xyz="0 0 0"
          rpy="0 0 0" />
        <geometry>
          <mesh
            filename="package://egu_description/meshes/base_link.${meshType}" />
        </geometry>
      </collision>
    </link>

    <link name="${prefix}symbol_1_left">
      <inertial>
        <origin
          xyz="-0.00014475 -7.7141E-05 -1.6517E-07"
          rpy="0 0 0" />
        <mass
          value="0.00028259" />
        <inertia
          ixx="1.9364E-08"
          ixy="-1.2932E-12"
          ixz="-2.7689E-15"
          iyy="1.2696E-09"
          iyz="-1.5694E-12"
          izz="1.8096E-08" />
      </inertial>
      <visual>
        <origin
          xyz="0 0 0"
          rpy="0 0 0" />
        <geometry>
          <mesh
            filename="package://egu_description/meshes/symbol_1_left.${meshType}" />
        </geometry>
        <material name="light_blue_1" />
      </visual>
      <collision>
        <origin
          xyz="0 0 0"
          rpy="0 0 0" />
        <geometry>
          <mesh
            filename="package://egu_description/meshes/symbol_1_left.${meshType}" />
        </geometry>
      </collision>
    </link>

    <link name="${prefix}symbo_1_right">
      <inertial>
        <origin
          xyz="0.00014475 7.7141E-05 -1.6517E-07"
          rpy="0 0 0" />
        <mass
          value="0.00028259" />
        <inertia
          ixx="1.9364E-08"
          ixy="-1.2932E-12"
          ixz="2.7689E-15"
          iyy="1.2696E-09"
          iyz="1.5694E-12"
          izz="1.8096E-08" />
      </inertial>
      <visual>
        <origin
          xyz="0 0 0"
          rpy="0 0 0" />
        <geometry>
          <mesh
            filename="package://egu_description/meshes/symbol_1_right.${meshType}" />
        </geometry>
        <material name="light_blue_1" />
      </visual>
      <collision>
        <origin
          xyz="0 0 0"
          rpy="0 0 0" />
        <geometry>
          <mesh
            filename="package://egu_description/meshes/symbol_1_right.${meshType}" />
        </geometry>
      </collision>
    </link>

    <link
      name="${prefix}translational_left">
      <inertial>
        <origin
          xyz="-1.4263E-11 -1.7621E-09 -0.0072452"
          rpy="0 0 0" />
        <mass
          value="0.023586" />
        <inertia
          ixx="4.5433E-06"
          ixy="-1.0067E-14"
          ixz="3.9379E-16"
          iyy="3.0604E-07"
          iyz="9.2402E-14"
          izz="4.5738E-06" />
      </inertial>
      <visual>
        <origin
          xyz="0 0 0"
          rpy="0 0 0" />
        <geometry>
          <mesh
            filename="package://egu_description/meshes/translational_left.${meshType}" />
        </geometry>
        <material name="light_grey" />
      </visual>
      <collision>
        <origin
          xyz="0 0 0"
          rpy="0 0 0" />
        <geometry>
          <mesh
            filename="package://egu_description/meshes/translational_left.${meshType}" />
        </geometry>
      </collision>
    </link>

    <link
      name="${prefix}translational_right">
      <inertial>
        <origin
          xyz="1.4263E-11 1.7621E-09 -0.0072452"
          rpy="0 0 0" />
        <mass
          value="0.023586" />
        <inertia
          ixx="4.5433E-06"
          ixy="-1.0067E-14"
          ixz="-3.9379E-16"
          iyy="3.0604E-07"
          iyz="-9.2402E-14"
          izz="4.5738E-06" />
      </inertial>
      <visual>
        <origin
          xyz="0 0 0"
          rpy="0 0 0" />
        <geometry>
          <mesh
            filename="package://egu_description/meshes/translational_right.${meshType}" />
        </geometry>
        <material name="light_grey" />
      </visual>
      <collision>
        <origin
          xyz="0 0 0"
          rpy="0 0 0" />
        <geometry>
          <mesh
            filename="package://egu_description/meshes/translational_right.${meshType}" />
        </geometry>
      </collision>
    </link>

    <!-- joints -->
    <joint
      name="${prefix}fixed_joint_symbol_1_left"
      type="fixed">
      <origin
        xyz="0 0.0353 0.0701"
        rpy="0 0 0" />
      <parent
        link="${prefix}base_link" />
      <child
        link="${prefix}symbol_1_left" />
      <axis
        xyz="0 0 0" />
    </joint>

    <joint
      name="${prefix}fixed_joint_symbol_1_right"
      type="fixed">
      <origin
        xyz="0 -0.0353 0.0701"
        rpy="0 0 0" />
      <parent
        link="${prefix}base_link" />
      <child
        link="${prefix}symbo_1_right" />
      <axis
        xyz="0 0 0" />
    </joint>
    
    <joint
      name="${prefix}prismatic_1"
      type="prismatic">
      <origin
        xyz="-0.01258 0.01265 0.083"
        rpy="0 0 0" />
      <parent
        link="${prefix}base_link" />
      <child
        link="${prefix}translational_left" />
      <axis
        xyz="1 0 0" />
      <limit
        lower="-0.012"
        upper="0.039"
        effort="300"
        velocity="0.11" />
      <dynamics damping="0.3" friction="0.2"  />
    </joint>

    <joint
      name="${prefix}prismatic_2"
      type="prismatic">
      <origin
        xyz="0.01258 -0.01265 0.083"
        rpy="0 0 0" />
      <parent
        link="${prefix}base_link" />
      <child
        link="${prefix}translational_right" />
      <axis
        xyz="1 0 0" />
      <limit
        lower="-0.039"
        upper="0.012"
        effort="300"
        velocity="0.11" />
      <mimic joint="${prefix}prismatic_1" multiplier="-1" offset="0" /> 
      <dynamics damping="0.3" friction="0.2" />
    </joint>
  </xacro:macro>
</robot>