<?xml version="1.0" ?>
<!-- =================================================================================== -->
<!-- |    This document was autogenerated by xacro from pzn_plus.urdf.xacro            | -->
<!-- |    EDITING THIS FILE BY HAND IS NOT RECOMMENDED                                 | -->
<!-- =================================================================================== -->
<robot name="pzn_plus">
  <!--degrees to radians-->
  <!-- xacro:pzn_plus_base_link prefix="" meshType="dae" / -->
  <!-- xacro:pzn_plus_fingers_link prefix="" meshType="dae" / -->
  <!-- xacro:pzn_plus_transmission prefix=""  / -->
  <!-- links -->
  <link name="pzn_plus_base_link">
    <inertial>
      <origin rpy="0 0 0" xyz="-3.72573931268341E-05 0.000318338201142255 0.0127328982984143"/>
      <mass value="0.0307377335375316"/>
      <inertia ixx="4.77894957339341E-06" ixy="-1.95335252616781E-09" ixz="1.69640432077875E-09" iyy="4.85993064937264E-06" iyz="-1.81146687762425E-08" izz="7.49495167832347E-06"/>
    </inertial>
    <visual>
      <origin rpy="0 0 0" xyz="0 0 0"/>
      <geometry>
        <mesh filename="package://pzn_plus_description/meshes/pzn_plus_base.dae"/>
      </geometry>
      <material name="">
        <color rgba="0.517647058823529 0.517647058823529 0 1"/>
      </material>
    </visual>
    <collision>
      <origin rpy="0 0 0" xyz="0 0 0"/>
      <geometry>
        <mesh filename="package://pzn_plus_description/meshes/pzn_plus_base.dae"/>
      </geometry>
    </collision>
  </link>
  <link name="pzn_plus_trans_1">
    <inertial>
      <origin rpy="0 0 0" xyz="-3.57849226535115E-10 0.0108765381400886 -0.000315367044710781"/>
      <mass value="0.00162889478244803"/>
      <inertia ixx="7.49822342198456E-08" ixy="-1.27842770643375E-16" ixz="-2.44691269921564E-15" iyy="2.23913080422873E-08" iyz="1.44435754323217E-09" izz="7.75810628622913E-08"/>
    </inertial>
    <visual>
      <origin rpy="0 0 0" xyz="-0.0016 0.022 -0.0045"/>
      <geometry>
        <mesh filename="package://pzn_plus_description/meshes/pzn_plus_trans.dae"/>
      </geometry>
      <material name="">
        <color rgba="0.180392156862745 0.180392156862745 0.180392156862745 1"/>
      </material>
    </visual>
    <collision>
      <origin rpy="0 0 0" xyz="-0.0016 0.022 -0.0045"/>
      <geometry>
        <mesh filename="package://pzn_plus_description/meshes/pzn_plus_trans.dae"/>
      </geometry>
    </collision>
  </link>
  <link name="pzn_plus_trans_2">
    <inertial>
      <origin rpy="0 0 0" xyz="-3.58109043287202E-10 0.0108765388192112 -0.00031536704443285"/>
      <mass value="0.00162889478115007"/>
      <inertia ixx="7.498223362452E-08" ixy="-1.83887864245355E-16" ixz="-2.4469784777142E-15" iyy="2.23913080100562E-08" iyz="1.44435775103784E-09" izz="7.75810622404117E-08"/>
    </inertial>
    <visual>
      <origin rpy="0 0 0" xyz="-0.0016 0.022 -0.0045"/>
      <geometry>
        <mesh filename="package://pzn_plus_description/meshes/pzn_plus_trans.dae"/>
      </geometry>
      <material name="">
        <color rgba="0.180392156862745 0.180392156862745 0.180392156862745 1"/>
      </material>
    </visual>
    <collision>
      <origin rpy="0 0 0" xyz="-0.0016 0.022 -0.0045"/>
      <geometry>
        <mesh filename="package://pzn_plus_description/meshes/pzn_plus_trans.dae"/>
      </geometry>
    </collision>
  </link>
  <link name="pzn_plus_trans_3">
    <inertial>
      <origin rpy="0 0 0" xyz="-3.58109044154564E-10 0.0108765388192112 -0.00031536704443285"/>
      <mass value="0.00162889478115007"/>
      <inertia ixx="7.49822336245201E-08" ixy="-1.83887845220201E-16" ixz="-2.446978477921E-15" iyy="2.23913080100562E-08" iyz="1.44435775103783E-09" izz="7.75810622404117E-08"/>
    </inertial>
    <visual>
      <origin rpy="0 0 0" xyz="-0.0016 0.022 -0.0045"/>
      <geometry>
        <mesh filename="package://pzn_plus_description/meshes/pzn_plus_trans.dae"/>
      </geometry>
      <material name="">
        <color rgba="0.180392156862745 0.180392156862745 0.180392156862745 1"/>
      </material>
    </visual>
    <collision>
      <origin rpy="0 0 0" xyz="-0.0016 0.022 -0.0045"/>
      <geometry>
        <mesh filename="package://pzn_plus_description/meshes/pzn_plus_trans.dae"/>
      </geometry>
    </collision>
  </link>
  <joint name="pzn_plus_prismatic_1" type="prismatic">
    <origin rpy="0 0 -0.523598775598" xyz="-0.01124 -0.0227105829743 0.022187"/>
    <parent link="pzn_plus_base_link"/>
    <child link="pzn_plus_trans_1"/>
    <axis xyz="0 1 0"/>
    <limit effort="300" lower="-0.015" upper="0" velocity="1"/>
  </joint>
  <joint name="pzn_plus_prismatic_2" type="prismatic">
    <origin rpy="0 0 1.5708012244" xyz="0.0252 0.00157 0.022187"/>
    <parent link="pzn_plus_base_link"/>
    <child link="pzn_plus_trans_2"/>
    <axis xyz="0 1 0"/>
    <limit effort="300" lower="-0.015" upper="0" velocity="1"/>
    <mimic joint="pzn_plus_prismatic_1" multiplier="1" offset="0"/>
  </joint>
  <joint name="pzn_plus_prismatic_3" type="prismatic">
    <origin rpy="0 0 -2.617921602390" xyz="-0.01397735 0.021 0.0221865670970663"/>
    <parent link="pzn_plus_base_link"/>
    <child link="pzn_plus_trans_3"/>
    <axis xyz="0 1 0"/>
    <limit effort="300" lower="-0.015" upper="0" velocity="1"/>
    <mimic joint="pzn_plus_prismatic_1" multiplier="1" offset="0"/>
  </joint>
  <!-- links -->
  <link name="pzn_plus_finger_1">
    <inertial>
      <origin rpy="0 0 0" xyz="-1.7793206712053E-05 0.0105466571996601 0.0138490825923717"/>
      <mass value="0.00453123049399013"/>
      <inertia ixx="6.19390061820821E-07" ixy="7.11229380477195E-11" ixz="-1.27115655316891E-09" iyy="5.04845770684435E-07" iyz="6.06988981710161E-08" izz="2.014102697996E-07"/>
    </inertial>
    <visual>
      <origin rpy="0 0 0" xyz="-0.0001 0.0243 0"/>
      <geometry>
        <mesh filename="package://pzn_plus_description/meshes/pzn_plus_finger_1.dae"/>
      </geometry>
      <material name="">
        <color rgba="0.792156862745098 0.819607843137255 0.933333333333333 1"/>
      </material>
    </visual>
    <collision>
      <origin rpy="0 0 0" xyz="-0.0001 0.0243 0"/>
      <geometry>
        <mesh filename="package://pzn_plus_description/meshes/pzn_plus_finger_1.dae"/>
      </geometry>
    </collision>
  </link>
  <link name="pzn_plus_finger_2">
    <inertial>
      <origin rpy="0 0 0" xyz="-1.77932067122978E-05 0.0105466571996597 0.0138490825923717"/>
      <mass value="0.00453123049399013"/>
      <inertia ixx="6.19390061820822E-07" ixy="7.11229380476237E-11" ixz="-1.27115655316891E-09" iyy="5.04845770684436E-07" iyz="6.06988981710159E-08" izz="2.014102697996E-07"/>
    </inertial>
    <visual>
      <origin rpy="0 0 0" xyz="-0.0001 0.0243 0"/>
      <geometry>
        <mesh filename="package://pzn_plus_description/meshes/pzn_plus_finger_1.dae"/>
      </geometry>
      <material name="">
        <color rgba="0.792156862745098 0.819607843137255 0.933333333333333 1"/>
      </material>
    </visual>
    <collision>
      <origin rpy="0 0 0" xyz="-0.0001 0.0243 0"/>
      <geometry>
        <mesh filename="package://pzn_plus_description/meshes/pzn_plus_finger_1.dae"/>
      </geometry>
    </collision>
  </link>
  <link name="pzn_plus_finger_3">
    <inertial>
      <origin rpy="0 0 0" xyz="-1.77932067118042E-05 0.0105466571996597 0.0138490825923717"/>
      <mass value="0.00453123049399013"/>
      <inertia ixx="6.19390061820822E-07" ixy="7.11229380478619E-11" ixz="-1.27115655316895E-09" iyy="5.04845770684436E-07" iyz="6.06988981710161E-08" izz="2.014102697996E-07"/>
    </inertial>
    <visual>
      <origin rpy="0 0 0" xyz="-0.0001 0.0243 0"/>
      <geometry>
        <mesh filename="package://pzn_plus_description/meshes/pzn_plus_finger_1.dae"/>
      </geometry>
      <material name="">
        <color rgba="0.792156862745098 0.819607843137255 0.933333333333333 1"/>
      </material>
    </visual>
    <collision>
      <origin rpy="0 0 0" xyz="-0.0001 0.0243 0"/>
      <geometry>
        <mesh filename="package://pzn_plus_description/meshes/pzn_plus_finger_1.dae"/>
      </geometry>
    </collision>
  </link>
  <transmission name="trans_prismatic_joint_translational_1_effort">
    <type>transmission_interface/SimpleTransmission</type>
    <joint name="pzn_plus_prismatic_1">
      <hardwareInterface>hardware_interface/EffortJointInterface</hardwareInterface>
    </joint>
    <actuator name="prismatic_joint_translational_1_motor_effort">
      <hardwareInterface>hardware_interface/EffortJointInterface</hardwareInterface>
      <mechanicalReduction>1</mechanicalReduction>
    </actuator>
  </transmission>
  <gazebo>
    <plugin filename="libroboticsgroup_upatras_gazebo_mimic_joint_plugin.so" name="translational_2">
      <joint>pzn_plus_prismatic_1</joint>
      <mimicJoint>pzn_plus_prismatic_2</mimicJoint>
      <multiplier>1</multiplier>
      <offset>0</offset>
    </plugin>
  </gazebo>
  <gazebo>
    <plugin filename="libroboticsgroup_upatras_gazebo_mimic_joint_plugin.so" name="translational_3">
      <joint>pzn_plus_prismatic_1</joint>
      <mimicJoint>pzn_plus_prismatic_3</mimicJoint>
      <multiplier>1</multiplier>
      <offset>0</offset>
    </plugin>
  </gazebo>
  <!-- links -->
  <!--link name="world" /-->
  <!--
        <joint name="fixed" type="fixed">
            <parent link="world" />
            <child link="${prefix}base_link" />
        </joint>
-->
  <joint name="pzn_plus_finger_1" type="fixed">
    <origin rpy="0 0 0" xyz="-0.00147 0.0005 0.0050134"/>
    <parent link="pzn_plus_trans_1"/>
    <child link="pzn_plus_finger_1"/>
    <axis xyz="0 0 0"/>
  </joint>
  <joint name="pzn_plus_finger_2" type="fixed">
    <origin rpy="0 0 0" xyz="-0.00147 0.0005 0.00501343290293372"/>
    <parent link="pzn_plus_trans_2"/>
    <child link="pzn_plus_finger_2"/>
    <axis xyz="0 0 0"/>
  </joint>
  <joint name="pzn_plus_finger_3" type="fixed">
    <origin rpy="0 0 0" xyz="-0.00147 0.0005 0.00501343290293372"/>
    <parent link="pzn_plus_trans_3"/>
    <child link="pzn_plus_finger_3"/>
    <axis xyz="0 0 0"/>
  </joint>
</robot>

