<?xml version="1.0" ?>
<robot xmlns:xacro="http://ros.org/wiki/xacro">
<xacro:macro name="motoman_gp165r_equipped" params="prefix">

    <!-- Properties -->
    <xacro:include filename="$(find motoman_resources)/urdf/common_materials.xacro"/>

    <!-- link list -->
    <link name="${prefix}base_link">
        <visual>
            <geometry>
                <mesh filename="package://motoman_gp165r_support/meshes/gp165r/visual/base_link.dae"/>
            </geometry>
            <xacro:material_yaskawa_blue/>
        </visual>
        <collision>
            <geometry>
                <mesh filename="package://motoman_gp165r_support/meshes/gp165r/collision/base_link.stl"/>
            </geometry>
        </collision>
    </link>
    <link name="${prefix}link_1_s">
        <visual>
            <geometry>
                <mesh filename="package://motoman_gp165r_support/meshes/gp165r/visual/link_1_s.dae"/>
            </geometry>
            <xacro:material_yaskawa_blue/>
        </visual>
        <collision>
            <geometry>
                <mesh filename="package://motoman_gp165r_support/meshes/gp165r/collision/link_1_s.stl"/>
            </geometry>
        </collision>
    </link>
    <link name="${prefix}link_2_l">
        <visual>
            <geometry>
                <mesh filename="package://motoman_gp165r_support/meshes/gp165r/visual/link_2_l.dae"/>
            </geometry>
            <xacro:material_yaskawa_blue/>
        </visual>
        <collision>
            <geometry>
                <mesh filename="package://motoman_gp165r_support/meshes/gp165r/collision/link_2_l.stl"/>
            </geometry>
        </collision>
    </link>
    <link name="${prefix}link_3_u">
        <visual>
            <geometry>
                <mesh filename="package://motoman_gp165r_support/meshes/gp165r/visual/link_3_u.dae"/>
            </geometry>
            <xacro:material_yaskawa_blue/>
        </visual>
        <collision>
            <geometry>
                <mesh filename="package://motoman_gp165r_support/meshes/gp165r/collision/link_3_u.stl"/>
            </geometry>
        </collision>
    </link>
    <link name="${prefix}link_4_r">
        <visual>
            <geometry>
                <mesh filename="package://motoman_gp165r_support/meshes/gp165r/visual/link_4_r.dae"/>
            </geometry>
            <xacro:material_yaskawa_blue/>
        </visual>
        <collision>
            <geometry>
                <mesh filename="package://motoman_gp165r_support/meshes/gp165r/collision/link_4_r.stl"/>
            </geometry>
        </collision>
    </link>
    <link name="${prefix}link_5_b">
        <visual>
            <geometry>
                <mesh filename="package://motoman_gp165r_support/meshes/gp165r/visual/link_5_b.dae"/>
            </geometry>
            <xacro:material_yaskawa_blue/>
        </visual>
        <collision>
            <geometry>
                <mesh filename="package://motoman_gp165r_support/meshes/gp165r/collision/link_5_b.stl"/>
            </geometry>
        </collision>
    </link>
    <link name="${prefix}link_6_t">
        <visual>
            <geometry>
                <mesh filename="package://motoman_gp165r_support/meshes/gp165r/visual/link_6_t.dae"/>
            </geometry>
            <xacro:material_yaskawa_blue/>
        </visual>
        <collision>
            <geometry>
                <mesh filename="package://motoman_gp165r_support/meshes/gp165r/collision/link_6_t.stl"/>
            </geometry>
        </collision>
    </link>
    <!-- end of link list -->

    <!-- joint list -->
    <joint name="${prefix}joint_1_s" type="revolute">
        <parent link="${prefix}base_link"/>
        <child link="${prefix}link_1_s"/>
        <origin xyz="0 0 0.450" rpy="0 0 0" />
        <axis xyz="0 0 1" />
        <limit lower="${radians(-180)}" upper="${radians(180)}" effort="7845.32" velocity="${radians(105)}"/>
    </joint>
    <joint name="${prefix}joint_2_l" type="revolute">
        <parent link="${prefix}link_1_s"/>
        <child link="${prefix}link_2_l"/>
        <origin xyz="0.740 0 0" rpy="0 0 0" />
        <axis xyz="0 1 0" />
        <limit lower="${radians(-130)}" upper="${radians(80)}" effort="10480.86" velocity="${radians(105)}"/>
    </joint>
    <joint name="${prefix}joint_3_u" type="revolute">
        <parent link="${prefix}link_2_l"/>
        <child link="${prefix}link_3_u"/>
        <origin xyz="1.150 0 0" rpy="0 0 0" />
        <axis xyz="0 -1 0" />
        <limit lower="${radians(-79.4)}" upper="${radians(78)}" effort="7688.41" velocity="${radians(105)}"/>
    </joint>
    <joint name="${prefix}joint_4_r" type="revolute">
        <parent link="${prefix}link_3_u"/>
        <child link="${prefix}link_4_r"/>
        <origin xyz="0.250 0 -1.225" rpy="0 0 0" />
        <axis xyz="0 0 1" />
        <limit lower="${radians(-205)}" upper="${radians(205)}" effort="1434.32" velocity="${radians(175)}"/>
    </joint>
    <joint name="${prefix}joint_5_b" type="revolute">
        <parent link="${prefix}link_4_r"/>
        <child link="${prefix}link_5_b"/>
        <origin xyz="0 0 0" rpy="0 0 0" />
        <axis xyz="0 -1 0" />
        <limit lower="${radians(-120)}" upper="${radians(120)}" effort="1434.32" velocity="${radians(150)}"/>
    </joint>
    <joint name="${prefix}joint_6_t" type="revolute">
        <parent link="${prefix}link_5_b"/>
        <child link="${prefix}link_6_t"/>
        <origin xyz="0 0 0" rpy="0 0 0" />
        <axis xyz="0 0 1" />
        <limit lower="${radians(-180)}" upper="${radians(180)}" effort="772.27" velocity="${radians(240)}"/>
    </joint>
    <!-- end of joint list -->

    <!-- ROS base_link to Robot Manufacturer World Coordinates transform -->
    <link name="${prefix}base" />
    <joint name="${prefix}base_link-base" type="fixed">
        <origin xyz="0 0 0.450" rpy="0 0 0"/>
        <parent link="${prefix}base_link"/>
        <child link="${prefix}base"/>
    </joint>

    <!-- ROS-Industrial 'flange' frame: attachment point for EEF models -->
    <link name="${prefix}flange"/>
    <joint name="${prefix}joint_6_t-flange" type="fixed">
      <origin xyz="0 0 -0.225" rpy="0 0 0"/>
      <parent link="${prefix}link_6_t"/>
      <child link="${prefix}flange"/>
    </joint>

    <!-- ROS-Industrial 'tool0' frame: all-zeros tool frame -->
    <link name="${prefix}tool0"/>
    <joint name="${prefix}flange-tool0" type="fixed">
      <origin xyz="0 0 0" rpy="${radians(180)} ${radians(-90)} 0"/>
      <parent link="${prefix}flange"/>
      <child link="${prefix}tool0"/>
    </joint>

</xacro:macro>
</robot>
