<?xml version="1.0" encoding="utf-8"?>
<!-- This URDF was automatically created by SolidWorks to URDF Exporter! Originally created by Stephen Brawner (brawner@gmail.com) 
     Commit Version: 1.6.0-4-g7f85cfe  Build Version: 1.6.7995.38578
     For more information, please see http://wiki.ros.org/sw_urdf_exporter -->
<robot
  name="robot">
  <link
    name="base_link">
    <inertial>
      <origin
        xyz="0.14971 -0.27802 0.15406"
        rpy="0 0 0" />
      <mass
        value="1.232" />
      <inertia
        ixx="0.028709"
        ixy="1.0903E-17"
        ixz="1.2318E-17"
        iyy="0.028709"
        iyz="3.8324E-18"
        izz="0.048069" />
    </inertial>
    <visual>
      <origin
        xyz="0 0 0"
        rpy="0 0 0" />
      <geometry>
        <mesh
          filename="package://example-robot-data/robots/custom_mobile_robots/custom_mobile_robot_description/meshes/base_link.dae" />
      </geometry>
      <material
        name="">
        <color
          rgba="0.8 0.81961 0.93333 1" />
      </material>
    </visual>
    <collision>
      <origin
        xyz="0 0 0"
        rpy="0 0 0" />
      <geometry>
        <mesh
          filename="package://example-robot-data/robots/custom_mobile_robots/custom_mobile_robot_description/meshes/base_link.dae" />
      </geometry>
    </collision>
  </link>
  <link
    name="topcover">
    <inertial>
      <origin
        xyz="0.2913 -0.075 -0.31528"
        rpy="0 0 0" />
      <mass
        value="1.3108" />
      <inertia
        ixx="0.013383"
        ixy="-1.2052E-20"
        ixz="-1.5056E-18"
        iyy="0.026761"
        iyz="0"
        izz="0.013383" />
    </inertial>
    <visual>
      <origin
        xyz="0 0 0"
        rpy="0 0 0" />
      <geometry>
        <mesh
          filename="package://example-robot-data/robots/custom_mobile_robots/custom_mobile_robot_description/meshes/topcover.dae" />
      </geometry>
      <material
        name="">
        <color
          rgba="0 0 0.5 0.35" />
      </material>
    </visual>
    <collision>
      <origin
        xyz="0 0 0"
        rpy="0 0 0" />
      <geometry>
        <mesh
          filename="package://example-robot-data/robots/custom_mobile_robots/custom_mobile_robot_description/meshes/topcover.dae" />
      </geometry>
    </collision>
  </link>
  <joint
    name="topcover"
    type="fixed">
    <origin
      xyz="-0.14159 -0.5933 0.22906"
      rpy="1.5708 0 0" />
    <parent
      link="base_link" />
    <child
      link="topcover" />
    <axis
      xyz="0 0 0" />
  </joint>
  <link
    name="camerapole">
    <inertial>
      <origin
        xyz="0.2536 0.01 -0.0658"
        rpy="0 0 0" />
      <mass
        value="0.16" />
      <inertia
        ixx="1.0667E-05"
        ixy="-1.2787E-20"
        ixz="1.0994E-19"
        iyy="0.0021387"
        iyz="8.5389E-23"
        izz="0.0021387" />
    </inertial>
    <visual>
      <origin
        xyz="0 0 0"
        rpy="0 0 0" />
      <geometry>
        <mesh
          filename="package://example-robot-data/robots/custom_mobile_robots/custom_mobile_robot_description/meshes/camerapole.dae" />
      </geometry>
      <material
        name="">
        <color
          rgba="192 192 192 1" />
      </material>
    </visual>
    <collision>
      <origin
        xyz="0 0 0"
        rpy="0 0 0" />
      <geometry>
        <mesh
          filename="package://example-robot-data/robots/custom_mobile_robots/custom_mobile_robot_description/meshes/camerapole.dae" />
      </geometry>
    </collision>
  </link>
  <joint
    name="camerapole"
    type="fixed">
    <origin
      xyz="0.30971 -0.34384 0.68236"
      rpy="1.5708 1.5708 0" />
    <parent
      link="base_link" />
    <child
      link="camerapole" />
    <axis
      xyz="0 0 0" />
  </joint>
  <link
    name="camera">
    <inertial>
      <origin
        xyz="0.0017627 -0.025373 -0.024805"
        rpy="0 0 0" />
      <mass
        value="0.056475" />
      <inertia
        ixx="1.2826E-05"
        ixy="4.6112E-11"
        ixz="-2.5744E-11"
        iyy="1.5962E-05"
        iyz="-1.0096E-06"
        izz="1.0085E-05" />
    </inertial>
    <visual>
      <origin
        xyz="0 0 0"
        rpy="0 0 0" />
      <geometry>
        <mesh
          filename="package://example-robot-data/robots/custom_mobile_robots/custom_mobile_robot_description/meshes/camera.dae" />
      </geometry>
      <material
        name="">
        <color
          rgba="0 0 0 1" />
      </material>
    </visual>
    <collision>
      <origin
        xyz="0 0 0"
        rpy="0 0 0" />
      <geometry>
        <mesh
          filename="package://example-robot-data/robots/custom_mobile_robots/custom_mobile_robot_description/meshes/camera.dae" />
      </geometry>
    </collision>
  </link>
  <joint
    name="camera"
    type="continuous">
    <origin
      xyz="0 0.0200000000000002 -0.0657999999999869"
      rpy="1.47548340501541 1.5707963267949 0" />
    <parent
      link="camerapole" />
    <child
      link="camera" />
    <axis
      xyz="0 0.99546116114247 -0.0951686747668852" />
  </joint>
  <link
    name="motorclamp1">
    <inertial>
      <origin
        xyz="0.009919 -0.0070219 -0.0059495"
        rpy="0 0 0" />
      <mass
        value="0.017347" />
      <inertia
        ixx="2.8855E-06"
        ixy="3.175E-07"
        ixz="-1.4271E-22"
        iyy="9.433E-06"
        iyz="-2.2744E-22"
        izz="1.1839E-05" />
    </inertial>
    <visual>
      <origin
        xyz="0 0 0"
        rpy="0 0 0" />
      <geometry>
        <mesh
          filename="package://example-robot-data/robots/custom_mobile_robots/custom_mobile_robot_description/meshes/motorclamp1.dae" />
      </geometry>
      <material
        name="">
        <color
          rgba="0.79216 0.81961 0.93333 1" />
      </material>
    </visual>
    <collision>
      <origin
        xyz="0 0 0"
        rpy="0 0 0" />
      <geometry>
        <mesh
          filename="package://example-robot-data/robots/custom_mobile_robots/custom_mobile_robot_description/meshes/motorclamp1.dae" />
      </geometry>
    </collision>
  </link>
  <joint
    name="motorclamp1"
    type="fixed">
    <origin
      xyz="0.0835361437494156 -0.452618990455206 0.121441134925834"
      rpy="1.5707963267949 0 0" />
    <parent
      link="base_link" />
    <child
      link="motorclamp1" />
    <axis
      xyz="0 0 0" />
  </joint>
  <link
    name="motor1">
    <inertial>
      <origin
        xyz="0.0011314641560948 6.70085677166032E-05 -0.0144620677025696"
        rpy="0 0 0" />
      <mass
        value="0.0622953735077123" />
      <inertia
        ixx="1.00827961176307E-05"
        ixy="3.17637355220363E-22"
        ixz="3.5237894094759E-22"
        iyy="1.00295314289269E-05"
        iyz="1.38818387636653E-07"
        izz="1.02711944162877E-05" />
    </inertial>
    <visual>
      <origin
        xyz="0 0 0"
        rpy="0 0 0" />
      <geometry>
        <mesh
          filename="package://example-robot-data/robots/custom_mobile_robots/custom_mobile_robot_description/meshes/motor1.dae" />
      </geometry>
      <material
        name="">
        <color
          rgba="0.792156862745098 0.819607843137255 0.933333333333333 1" />
      </material>
    </visual>
    <collision>
      <origin
        xyz="0 0 0"
        rpy="0 0 0" />
      <geometry>
        <mesh
          filename="package://example-robot-data/robots/custom_mobile_robots/custom_mobile_robot_description/meshes/motor1.dae" />
      </geometry>
    </collision>
  </link>
  <joint
    name="motor1"
    type="continuous">
    <origin
      xyz="0.01 0 0"
      rpy="0 0 -0.061731" />
    <parent
      link="motorclamp1" />
    <child
      link="motor1" />
    <axis
      xyz="0 0 1" />
  </joint>
  <link
    name="wheel1">
    <inertial>
      <origin
        xyz="4.1633E-17 1.249E-16 0.0125"
        rpy="0 0 0" />
      <mass
        value="3.0701" />
      <inertia
        ixx="0.0094347"
        ixy="2.7105E-18"
        ixz="-2.0382E-19"
        iyy="0.0094347"
        iyz="1.3375E-19"
        izz="0.018654" />
    </inertial>
    <visual>
      <origin
        xyz="0 0 0"
        rpy="0 0 0" />
      <geometry>
        <mesh
          filename="package://example-robot-data/robots/custom_mobile_robots/custom_mobile_robot_description/meshes/wheel1.dae" />
      </geometry>
      <material
        name="">
        <color
          rgba="0 0 0 1" />
      </material>
    </visual>
    <collision>
      <origin
        xyz="0 0 0"
        rpy="0 0 0" />
      <geometry>
        <mesh
          filename="package://example-robot-data/robots/custom_mobile_robots/custom_mobile_robot_description/meshes/wheel1.dae" />
      </geometry>
    </collision>
  </link>
  <joint
    name="wheel1`"
    type="revolute">
    <origin
      xyz="0.00113146415609412 -0.00681576240594288 0.019200504127415"
      rpy="0 0 -0.0466862389972134" />
    <parent
      link="motor1" />
    <child
      link="wheel1" />
    <axis
      xyz="0 0 1" />
    <limit
      lower="0"
      upper="0"
      effort="0"
      velocity="0" />
  </joint>
  <link
    name="motorclamp2">
    <inertial>
      <origin
        xyz="0.00991903249259808 -0.00702191432039451 -0.00594949587258495"
        rpy="0 0 0" />
      <mass
        value="0.0173472817028446" />
      <inertia
        ixx="2.88547454674582E-06"
        ixy="3.1750180352986E-07"
        ixz="-1.23512494461037E-22"
        iyy="9.43304633892377E-06"
        iyz="-5.72978926409721E-22"
        izz="1.18386136024184E-05" />
    </inertial>
    <visual>
      <origin
        xyz="0 0 0"
        rpy="0 0 0" />
      <geometry>
        <mesh
          filename="package://example-robot-data/robots/custom_mobile_robots/custom_mobile_robot_description/meshes/motorclamp2.dae" />
      </geometry>
      <material
        name="">
        <color
          rgba="0.792156862745098 0.819607843137255 0.933333333333333 1" />
      </material>
    </visual>
    <collision>
      <origin
        xyz="0 0 0"
        rpy="0 0 0" />
      <geometry>
        <mesh
          filename="package://example-robot-data/robots/custom_mobile_robots/custom_mobile_robot_description/meshes/motorclamp2.dae" />
      </geometry>
    </collision>
  </link>
  <joint
    name="motorclamp2"
    type="fixed">
    <origin
      xyz="0.083573 -0.11532 0.12144"
      rpy="1.5708 0 0" />
    <parent
      link="base_link" />
    <child
      link="motorclamp2" />
    <axis
      xyz="0 0 0" />
  </joint>
  <link
    name="motor2">
    <inertial>
      <origin
        xyz="-0.00114091742437558 -5.59543664885309E-06 -0.00256307595739959"
        rpy="0 0 0" />
      <mass
        value="0.0622953735077122" />
      <inertia
        ixx="1.00827961176307E-05"
        ixy="5.29395592033938E-23"
        ixz="3.77918142360165E-22"
        iyy="1.00295314289269E-05"
        iyz="1.38818387636653E-07"
        izz="1.02711944162877E-05" />
    </inertial>
    <visual>
      <origin
        xyz="0 0 0"
        rpy="0 0 0" />
      <geometry>
        <mesh
          filename="package://example-robot-data/robots/custom_mobile_robots/custom_mobile_robot_description/meshes/motor2.dae" />
      </geometry>
      <material
        name="">
        <color
          rgba="0.792156862745098 0.819607843137255 0.933333333333333 1" />
      </material>
    </visual>
    <collision>
      <origin
        xyz="0 0 0"
        rpy="0 0 0" />
      <geometry>
        <mesh
          filename="package://example-robot-data/robots/custom_mobile_robots/custom_mobile_robot_description/meshes/motor2.dae" />
      </geometry>
    </collision>
  </link>
  <joint
    name="motor2"
    type="continuous">
    <origin
      xyz="0.01 0 0"
      rpy="3.14159265358979 0 -3.13944414528986" />
    <parent
      link="motorclamp2" />
    <child
      link="motor2" />
    <axis
      xyz="0 0 1" />
  </joint>
  <link
    name="wheel2">
    <inertial>
      <origin
        xyz="5.5511E-17 8.3267E-17 -0.0125"
        rpy="0 0 0" />
      <mass
        value="3.0701" />
      <inertia
        ixx="0.0094347"
        ixy="2.9002E-18"
        ixz="-2.1593E-19"
        iyy="0.0094347"
        iyz="1.3138E-19"
        izz="0.018654" />
    </inertial>
    <visual>
      <origin
        xyz="0 0 0"
        rpy="0 0 0" />
      <geometry>
        <mesh
          filename="package://example-robot-data/robots/custom_mobile_robots/custom_mobile_robot_description/meshes/wheel2.dae" />
      </geometry>
      <material
        name="">
        <color
          rgba="0 0 0 1" />
      </material>
    </visual>
    <collision>
      <origin
        xyz="0 0 0"
        rpy="0 0 0" />
      <geometry>
        <mesh
          filename="package://example-robot-data/robots/custom_mobile_robots/custom_mobile_robot_description/meshes/wheel2.dae" />
      </geometry>
    </collision>
  </link>
  <joint
    name="wheel2"
    type="revolute">
    <origin
      xyz="-0.00114091742437562 -0.00688836641030763 0.030849495872585"
      rpy="3.14159265358979 0 3.09663167863098" />
    <parent
      link="motor2" />
    <child
      link="wheel2" />
    <axis
      xyz="0 0 1" />
    <limit
      lower="0"
      upper="0"
      effort="0"
      velocity="0" />
  </joint>
  <link
    name="castorwheel">
    <inertial>
      <origin
        xyz="0.016213 0.020589 -3.5773E-05"
        rpy="0 0 0" />
      <mass
        value="0.047654" />
      <inertia
        ixx="9.6734E-06"
        ixy="4.687E-07"
        ixz="6.9494E-10"
        iyy="1.1737E-05"
        iyz="-7.8849E-10"
        izz="1.3564E-05" />
    </inertial>
    <visual>
      <origin
        xyz="0 0 0"
        rpy="0 0 0" />
      <geometry>
        <mesh
          filename="package://example-robot-data/robots/custom_mobile_robots/custom_mobile_robot_description/meshes/castorwheel.dae" />
      </geometry>
      <material
        name="">
        <color
          rgba="0 0 0 1" />
      </material>
    </visual>
    <collision>
      <origin
        xyz="0 0 0"
        rpy="0 0 0" />
      <geometry>
        <mesh
          filename="package://example-robot-data/robots/custom_mobile_robots/custom_mobile_robot_description/meshes/castorwheel.dae" />
      </geometry>
    </collision>
  </link>
  <joint
    name="castorwheel"
    type="fixed">
    <origin
      xyz="0.31471 -0.27802 0.027055"
      rpy="1.5708 0 0.00093269" />
    <parent
      link="base_link" />
    <child
      link="castorwheel" />
    <axis
      xyz="0 0 0" />
    <limit
      lower="0"
      upper="0"
      effort="0"
      velocity="0" />
  </joint>
  <link
    name="sidecover">
    <inertial>
      <origin
        xyz="0 0 0"
        rpy="0 0 0" />
      <mass
        value="0" />
      <inertia
        ixx="0"
        ixy="0"
        ixz="0"
        iyy="0"
        iyz="0"
        izz="0" />
    </inertial>
    <visual>
      <origin
        xyz="0 0 0"
        rpy="0 0 0" />
      <geometry>
        <mesh
          filename="package://example-robot-data/robots/custom_mobile_robots/custom_mobile_robot_description/meshes/sidecover.dae" />
      </geometry>
      <material
        name="">
        <color
          rgba="1 1 1 1" />
      </material>
    </visual>
    <collision>
      <origin
        xyz="0 0 0"
        rpy="0 0 0" />
      <geometry>
        <mesh
          filename="package://example-robot-data/robots/custom_mobile_robots/custom_mobile_robot_description/meshes/sidecover.dae" />
      </geometry>
    </collision>
  </link>
  <joint
    name="sidecover"
    type="fixed">
    <origin
      xyz="0.32971327534043 -0.463019494582621 0.349983790955112"
      rpy="3.14159265358979 0 1.5707963267949" />
    <parent
      link="base_link" />
    <child
      link="sidecover" />
    <axis
      xyz="0 0 0" />
  </joint>
</robot>