<?xml version="1.0" encoding="utf-8"?>
<!-- =================================================================================== -->
<!-- |    This document was autogenerated by xacro from maira7M.urdf.xacro             | -->
<!-- |    EDITING THIS FILE BY HAND IS NOT RECOMMENDED                                 | -->
<!-- =================================================================================== -->
<robot name="maira7M" xmlns:controller="http://playerstage.sourceforge.net/gazebo/xmlschema/#controller" xmlns:interface="http://playerstage.sourceforge.net/gazebo/xmlschema/#interface" xmlns:sensor="http://playerstage.sourceforge.net/gazebo/xmlschema/#sensor">
  <material name="blue">
    <color rgba="0 0 0.8 1"/>
  </material>
  <material name="white">
    <color rgba="1 1 1 1"/>
  </material>
  <material name="MelonYellow">
    <color rgba="1.0 0.6 0.0 1.0"/>
  </material>
  <link name="maira7M_root_link"/>
  <joint name="maira7M_root_joint" type="fixed">
    <origin rpy="0 0 1.5708" xyz="0 0 0"/>
    <parent link="maira7M_root_link"/>
    <child link="maira7M_link0"/>
  </joint>
  <link name="maira7M_link0">
    <inertial>
      <mass value="2.133"/>
      <origin rpy="0 0 0" xyz="0.0 0.0 0.0"/>
      <inertia ixx="0.0" ixy="0.0" ixz="0.0" iyy="0.0" iyz="0.0" izz="0.0"/>
    </inertial>
    <visual>
      <origin rpy="0 0 0" xyz="0 0 0"/>
      <geometry>
        <mesh filename="package://example-robot-data/robots/neura_robotics/neura_robot_description-devel-maira7M/maira7M/meshes/Link0_body.stl"/>
      </geometry>
      <material name="white"/>
    </visual>
    <collision>
      <origin rpy="0 0 0" xyz="0 0 0"/>
      <geometry>
        <mesh filename="package://example-robot-data/robots/neura_robotics/neura_robot_description-devel-maira7M/maira7M/collision/Link0_body.stl"/>
      </geometry>
      <material name="white"/>
    </collision>
  </link>
  <joint name="maira7M_joint1" type="revolute">
    <origin rpy="1.57079632679 0 0" xyz="0 0 0"/>
    <axis xyz="0 1 0"/>
    <limit effort="432" lower="-3.14159" upper="3.14159" velocity="2.0944"/>
    <parent link="maira7M_link0"/>
    <child link="maira7M_link1"/>
  </joint>
  <link name="maira7M_link1">
    <inertial>
      <mass value="10.458"/>
      <origin rpy="0 0 0" xyz="0.013845 0.316366 0.0"/>
      <inertia ixx="0.1615" ixy="-0.0175" ixz="0.0" iyy="17.5" iyz="0.0" izz="0.1942"/>
    </inertial>
    <visual>
      <origin rpy="0 0 0" xyz="0 0 0"/>
      <geometry>
        <mesh filename="package://example-robot-data/robots/neura_robotics/neura_robot_description-devel-maira7M/maira7M/meshes/Link1_body.stl"/>
      </geometry>
      <material name="white"/>
    </visual>
    <visual>
      <geometry>
        <mesh filename="package://example-robot-data/robots/neura_robotics/neura_robot_description-devel-maira7M/maira7M/meshes/Link1_led.stl"/>
      </geometry>
      <material name="white"/>
    </visual>
    <visual>
      <geometry>
        <mesh filename="package://example-robot-data/robots/neura_robotics/neura_robot_description-devel-maira7M/maira7M/meshes/Link1_ring.stl"/>
      </geometry>
      <material name="white"/>
    </visual>
    <collision>
      <origin rpy="0 0 0" xyz="0 0 0"/>
      <geometry>
        <mesh filename="package://example-robot-data/robots/neura_robotics/neura_robot_description-devel-maira7M/maira7M/collision/Link1_body.stl"/>
      </geometry>
      <material name="white"/>
    </collision>
  </link>
  <joint name="maira7M_joint2" type="revolute">
    <origin rpy="0 0 4.89652762781e-12" xyz="0 0.438 0"/>
    <axis xyz="1 0 0"/>
    <limit effort="432" lower="-2.0944" upper="2.0944" velocity="2.0944"/>
    <parent link="maira7M_link1"/>
    <child link="maira7M_link2"/>
  </joint>
  <link name="maira7M_link2">
    <inertial>
      <mass value="14.8"/>
      <origin rpy="0 0 0" xyz="-0.05 0.06 -0.035"/>
      <inertia ixx="17.5" ixy="0.0011" ixz="0.0" iyy="0.1615" iyz="0.0" izz="0.12"/>
    </inertial>
    <visual>
      <origin rpy="0 0 0" xyz="0 0 0"/>
      <geometry>
        <mesh filename="package://example-robot-data/robots/neura_robotics/neura_robot_description-devel-maira7M/maira7M/meshes/Link2_body.stl"/>
      </geometry>
      <material name="white"/>
    </visual>
    <visual>
      <geometry>
        <mesh filename="package://example-robot-data/robots/neura_robotics/neura_robot_description-devel-maira7M/maira7M/meshes/Link2_led.stl"/>
      </geometry>
      <material name="white"/>
    </visual>
    <visual>
      <geometry>
        <mesh filename="package://example-robot-data/robots/neura_robotics/neura_robot_description-devel-maira7M/maira7M/meshes/Link2_ring.stl"/>
      </geometry>
      <material name="white"/>
    </visual>
    <collision>
      <origin rpy="0 0 0" xyz="0 0 0"/>
      <geometry>
        <mesh filename="package://example-robot-data/robots/neura_robotics/neura_robot_description-devel-maira7M/maira7M/collision/Link2_body.stl"/>
      </geometry>
      <material name="white"/>
    </collision>
  </link>
  <joint name="maira7M_joint3" type="revolute">
    <origin rpy="0 0 -4.89652762781e-12" xyz="0 0 0"/>
    <axis xyz="0 1 0"/>
    <limit effort="217" lower="-3.14159" upper="3.14159" velocity="2.618"/>
    <parent link="maira7M_link2"/>
    <child link="maira7M_link3"/>
  </joint>
  <link name="maira7M_link3">
    <inertial>
      <mass value="11.0"/>
      <origin rpy="0 0 0" xyz="-0.01 0.46 0.0"/>
      <inertia ixx="0.3927" ixy="-0.0251" ixz="0.0" iyy="3.5" iyz="0.0" izz="0.4118"/>
    </inertial>
    <visual>
      <origin rpy="0 0 0" xyz="0 0 0"/>
      <geometry>
        <mesh filename="package://example-robot-data/robots/neura_robotics/neura_robot_description-devel-maira7M/maira7M/meshes/Link3_body.stl"/>
      </geometry>
      <material name="white"/>
    </visual>
    <collision>
      <origin rpy="0 0 0" xyz="0 0 0"/>
      <geometry>
        <mesh filename="package://example-robot-data/robots/neura_robotics/neura_robot_description-devel-maira7M/maira7M/collision/Link3_body.stl"/>
      </geometry>
      <material name="white"/>
    </collision>
  </link>
  <joint name="maira7M_joint4" type="revolute">
    <origin rpy="0 0 4.89652762781e-12" xyz="0 0.7 0"/>
    <axis xyz="1 0 0"/>
    <limit effort="217" lower="-2.618" upper="2.618" velocity="2.618"/>
    <parent link="maira7M_link3"/>
    <child link="maira7M_link4"/>
  </joint>
  <link name="maira7M_link4">
    <inertial>
      <mass value="5.5"/>
      <origin rpy="0 0 0" xyz="-0.03 -0.01 0.0"/>
      <inertia ixx="3.5" ixy="0.0006" ixz="0.0" iyy="0.0113" iyz="0.0" izz="0.0215"/>
    </inertial>
    <visual>
      <origin rpy="0 0 0" xyz="0 0 0"/>
      <geometry>
        <mesh filename="package://example-robot-data/robots/neura_robotics/neura_robot_description-devel-maira7M/maira7M/meshes/Link4_body.stl"/>
      </geometry>
      <material name="white"/>
    </visual>
    <visual>
      <origin rpy="0 0 0" xyz="0 0 0"/>
      <geometry>
        <mesh filename="package://example-robot-data/robots/neura_robotics/neura_robot_description-devel-maira7M/maira7M/meshes/Link4_led.stl"/>
      </geometry>
      <material name="white"/>
    </visual>
    <visual>
      <origin rpy="0 0 0" xyz="0 0 0"/>
      <geometry>
        <mesh filename="package://example-robot-data/robots/neura_robotics/neura_robot_description-devel-maira7M/maira7M/meshes/Link4_ring.stl"/>
      </geometry>
      <material name="white"/>
    </visual>
    <collision>
      <origin rpy="0 0 0" xyz="0 0 0"/>
      <geometry>
        <mesh filename="package://example-robot-data/robots/neura_robotics/neura_robot_description-devel-maira7M/maira7M/collision/Link4_body.stl"/>
      </geometry>
      <material name="white"/>
    </collision>
  </link>
  <joint name="maira7M_joint5" type="revolute">
    <origin rpy="0 0 -4.89652762781e-12" xyz="0 0 0"/>
    <axis xyz="0 1 0"/>
    <limit effort="57" lower="-3.14159" upper="3.14159" velocity="3.8397"/>
    <parent link="maira7M_link4"/>
    <child link="maira7M_link5"/>
  </joint>
  <link name="maira7M_link5">
    <inertial>
      <mass value="8.0"/>
      <origin rpy="0 0 0" xyz="-0.06 0.37 0.0"/>
      <inertia ixx="0.3098" ixy="-0.0624" ixz="0.0" iyy="0.5" iyz="0.0" izz="0.3218"/>
    </inertial>
    <visual>
      <origin rpy="0 0 0" xyz="0 0 0"/>
      <geometry>
        <mesh filename="package://example-robot-data/robots/neura_robotics/neura_robot_description-devel-maira7M/maira7M/meshes/Link5_body.stl"/>
      </geometry>
      <material name="white"/>
    </visual>
    <collision>
      <origin rpy="0 0 0" xyz="0 0 0"/>
      <geometry>
        <mesh filename="package://example-robot-data/robots/neura_robotics/neura_robot_description-devel-maira7M/maira7M/collision/Link5_body.stl"/>
      </geometry>
      <material name="white"/>
    </collision>
  </link>
  <joint name="maira7M_joint6" type="revolute">
    <origin rpy="0 0 4.89652762781e-12" xyz="0 0.7 0"/>
    <axis xyz="1 0 0"/>
    <limit effort="57" lower="-3.14159" upper="3.14159" velocity="3.8397"/>
    <parent link="maira7M_link5"/>
    <child link="maira7M_link6"/>
  </joint>
  <link name="maira7M_link6">
    <inertial>
      <mass value="4.5"/>
      <origin rpy="0 0 0" xyz="-0.02 -0.04 -0.01"/>
      <inertia ixx="0.5" ixy="-0.0013" ixz="0.0" iyy="0.0085" iyz="0.0" izz="0.0126"/>
    </inertial>
    <visual>
      <origin rpy="0 0 0" xyz="0 0 0"/>
      <geometry>
        <mesh filename="package://example-robot-data/robots/neura_robotics/neura_robot_description-devel-maira7M/maira7M/meshes/Link6_body.stl"/>
      </geometry>
      <material name="white"/>
    </visual>
    <visual>
      <origin rpy="0 0 0" xyz="0 0 0"/>
      <geometry>
        <mesh filename="package://example-robot-data/robots/neura_robotics/neura_robot_description-devel-maira7M/maira7M/meshes/Link6_led.stl"/>
      </geometry>
      <material name="white"/>
    </visual>
    <visual>
      <origin rpy="0 0 0" xyz="0 0 0"/>
      <geometry>
        <mesh filename="package://example-robot-data/robots/neura_robotics/neura_robot_description-devel-maira7M/maira7M/meshes/Link6_ring.stl"/>
      </geometry>
      <material name="white"/>
    </visual>
    <visual>
      <origin rpy="0 0 0" xyz="0 0 0"/>
      <geometry>
        <mesh filename="package://example-robot-data/robots/neura_robotics/neura_robot_description-devel-maira7M/maira7M/meshes/Link6_sensors.stl"/>
      </geometry>
      <material name="white"/>
    </visual>
    <collision>
      <origin rpy="0 0 0" xyz="0 0 0"/>
      <geometry>
        <mesh filename="package://example-robot-data/robots/neura_robotics/neura_robot_description-devel-maira7M/maira7M/collision/Link6_body.stl"/>
      </geometry>
      <material name="white"/>
    </collision>
  </link>
  <joint name="maira7M_joint7" type="revolute">
    <origin rpy="0 0 -4.89652762781e-12" xyz="0 0 0"/>
    <axis xyz="0 1 0"/>
    <limit effort="37" lower="-3.14159" upper="3.14159" velocity="3.14159"/>
    <parent link="maira7M_link6"/>
    <child link="maira7M_link7"/>
  </joint>
  <link name="maira7M_link7">
    <inertial>
      <mass value="1.173"/>
      <origin rpy="0 0 0" xyz="0.0 0.165 0.0"/>
      <inertia ixx="0.0024" ixy="0.0" ixz="0.0" iyy="0.3" iyz="0.0" izz="0.0024"/>
    </inertial>
    <visual>
      <origin rpy="0 0 0" xyz="0 0 0"/>
      <geometry>
        <mesh filename="package://example-robot-data/robots/neura_robotics/neura_robot_description-devel-maira7M/maira7M/meshes/Link7_body.stl"/>
      </geometry>
      <material name="white"/>
    </visual>
    <visual>
      <origin rpy="0 0 0" xyz="0 0 0"/>
      <geometry>
        <mesh filename="package://example-robot-data/robots/neura_robotics/neura_robot_description-devel-maira7M/maira7M/meshes/Link7_led.stl"/>
      </geometry>
      <material name="white"/>
    </visual>
    <collision>
      <origin rpy="0 0 0" xyz="0 0 0"/>
      <geometry>
        <mesh filename="package://example-robot-data/robots/neura_robotics/neura_robot_description-devel-maira7M/maira7M/collision/Link7_body.stl"/>
      </geometry>
      <material name="white"/>
    </collision>
  </link>
  <link name="maira7M_flange"/>
  <joint name="maira7M_link7_to_flange" type="fixed">
    <origin rpy="-1.57079632679 -1.57079632679 0" xyz="0 0.115 0"/>
    <parent link="maira7M_link7"/>
    <child link="maira7M_flange"/>
  </joint>
  <link name="world"/>
  <joint name="world_joint" type="fixed">
    <parent link="world"/>
    <child link="maira7M_root_link"/>
    <origin rpy="0.0 0.0 0.0" xyz="0.0 0.0 0.0"/>
  </joint>
</robot>

