<?xml version="1.0" ?>
<!-- =================================================================================== -->
<!-- |    This document was autogenerated by xacro from egp.urdf.xacro                 | -->
<!-- |    EDITING THIS FILE BY HAND IS NOT RECOMMENDED                                 | -->
<!-- =================================================================================== -->
<robot name="egp">
  <!--degrees to radians-->
  <!-- xacro:egp_base_link prefix="" meshType="dae" / -->
  <!-- <xacro:include filename="$(find egp_description)/urdf/egp_fingers_link.urdf.xacro" /> -->
  <!-- xacro:egp_transmission prefix=""  / -->
  <!-- links -->
  <link name="egp_base_link">
    <inertial>
      <origin rpy="0 0 0" xyz="-1.3649E-05 0.00020804 0.053268"/>
      <mass value="0.23519"/>
      <inertia ixx="0.0003045" ixy="1.4187E-09" ixz="6.5932E-08" iyy="0.00024967" iyz="7.767E-07" izz="0.00010458"/>
    </inertial>
    <visual>
      <origin rpy="0 0 0" xyz="0 0 0"/>
      <geometry>
        <mesh filename="package://egp_description/meshes/egp_base.dae"/>
      </geometry>
      <material name="">
        <color rgba="0.79216 0.81961 0.93333 1"/>
      </material>
    </visual>
    <collision>
      <origin rpy="0 0 0" xyz="0 0 0"/>
      <geometry>
        <mesh filename="package://egp_description/meshes/egp_base.dae"/>
      </geometry>
    </collision>
  </link>
  <link name="egp_trans_1">
    <inertial>
      <origin rpy="0 0 0" xyz="0.0016208 0.02782 0.004811"/>
      <mass value="0.011095"/>
      <inertia ixx="3.553E-06" ixy="2.3867E-07" ixz="-1.9314E-07" iyy="1.0926E-06" iyz="7.2782E-07" izz="2.863E-06"/>
    </inertial>
    <visual>
      <origin rpy="0 0 0" xyz="-0.016 0.027 -0.00893"/>
      <geometry>
        <mesh filename="package://egp_description/meshes/egp_trans_1.dae"/>
      </geometry>
      <material name="">
        <color rgba="0.79216 0.81961 0.93333 1"/>
      </material>
    </visual>
    <collision>
      <origin rpy="0 0 0" xyz="-0.016 0.027 -0.00893"/>
      <geometry>
        <mesh filename="package://egp_description/meshes/egp_trans_1.dae"/>
      </geometry>
    </collision>
  </link>
  <link name="egp_trans_2">
    <inertial>
      <origin rpy="0 0 0" xyz="0.0016549 -0.037399 0.0049123"/>
      <mass value="0.010866"/>
      <inertia ixx="3.5456E-06" ixy="2.3867E-07" ixz="-1.9314E-07" iyy="1.0919E-06" iyz="7.2782E-07" izz="2.8556E-06"/>
    </inertial>
    <visual>
      <origin rpy="0 0 0" xyz="-0.016 -0.037 -0.00893"/>
      <geometry>
        <mesh filename="package://egp_description/meshes/egp_trans_2.dae"/>
      </geometry>
      <material name="">
        <color rgba="0.79216 0.81961 0.93333 1"/>
      </material>
    </visual>
    <collision>
      <origin rpy="0 0 0" xyz="-0.016 -0.037 -0.00893"/>
      <geometry>
        <mesh filename="package://egp_description/meshes/egp_trans_2.dae"/>
      </geometry>
    </collision>
  </link>
  <joint name="egp_prismatic_1" type="prismatic">
    <origin rpy="0 0 -1.570796" xyz="-0.059 -0.016075 0.10975"/>
    <parent link="egp_base_link"/>
    <child link="egp_trans_1"/>
    <axis xyz="0 1 0"/>
    <limit effort="300" lower="-0.03" upper="0.02" velocity="1"/>
    <dynamics damping="0.3" friction="0.2"/>
  </joint>
  <joint name="egp_prismatic_2" type="prismatic">
    <origin rpy="0 0 -1.570796" xyz="0.069 -0.016075 0.10975"/>
    <parent link="egp_base_link"/>
    <child link="egp_trans_2"/>
    <axis xyz="0 1 0"/>
    <limit effort="300" lower="-0.02" upper="0.03" velocity="1"/>
    <mimic joint="egp_prismatic_1" multiplier="-1" offset="0"/>
    <dynamics damping="0.3" friction="0.2"/>
  </joint>
  <transmission name="trans_prismatic_joint_translational_1_effort">
    <type>transmission_interface/SimpleTransmission</type>
    <joint name="egp_prismatic_1">
      <hardwareInterface>hardware_interface/EffortJointInterface</hardwareInterface>
    </joint>
    <actuator name="prismatic_joint_translational_1_motor_effort">
      <hardwareInterface>hardware_interface/EffortJointInterface</hardwareInterface>
      <mechanicalReduction>1</mechanicalReduction>
    </actuator>
  </transmission>
  <gazebo>
    <plugin filename="libroboticsgroup_upatras_gazebo_mimic_joint_plugin.so" name="translational_2">
      <joint>egp_prismatic_1</joint>
      <mimicJoint>egp_prismatic_2</mimicJoint>
      <multiplier>-1</multiplier>
      <offset>0</offset>
    </plugin>
  </gazebo>
  <!-- links -->
  <!--link name="world" /-->
  <!--
        <joint name="fixed" type="fixed">
            <parent link="world" />
            <child link="${prefix}base_link" />
        </joint>
-->
</robot>

